Watching for file changes with StatReloader
Watching for file changes with StatReloader
Not Found: /favicon.ico
Not Found: /favicon.ico
Not Found: /dashboard/
Not Found: /dashboard
D:\Dev\fuelmng\fuel_management\urls.py changed, reloading.
Watching for file changes with StatReloader
Watching for file changes with StatReloader
Not Found: /accounts/login/
Internal Server Error: /dashboard/driver/
Traceback (most recent call last):
  File "D:\Dev\fuelmng\venv\Lib\site-packages\django\core\handlers\exception.py", line 55, in inner
    response = get_response(request)
               ^^^^^^^^^^^^^^^^^^^^^
  File "D:\Dev\fuelmng\venv\Lib\site-packages\django\core\handlers\base.py", line 197, in _get_response
    response = wrapped_callback(request, *callback_args, **callback_kwargs)
               ^^^^^^^^^^^^^^^^^^^^^^^^^^^^^^^^^^^^^^^^^^^^^^^^^^^^^^^^^^^^
  File "D:\Dev\fuelmng\venv\Lib\site-packages\django\contrib\auth\decorators.py", line 23, in _wrapper_view
    return view_func(request, *args, **kwargs)
           ^^^^^^^^^^^^^^^^^^^^^^^^^^^^^^^^^^^
  File "D:\Dev\fuelmng\dashboard\views.py", line 96, in driver_dashboard
    return render(request, 'dashboard/driver_dashboard.html', context)
           ^^^^^^^^^^^^^^^^^^^^^^^^^^^^^^^^^^^^^^^^^^^^^^^^^^^^^^^^^^^
  File "D:\Dev\fuelmng\venv\Lib\site-packages\django\shortcuts.py", line 24, in render
    content = loader.render_to_string(template_name, context, request, using=using)
              ^^^^^^^^^^^^^^^^^^^^^^^^^^^^^^^^^^^^^^^^^^^^^^^^^^^^^^^^^^^^^^^^^^^^^
  File "D:\Dev\fuelmng\venv\Lib\site-packages\django\template\loader.py", line 61, in render_to_string
    template = get_template(template_name, using=using)
               ^^^^^^^^^^^^^^^^^^^^^^^^^^^^^^^^^^^^^^^^
  File "D:\Dev\fuelmng\venv\Lib\site-packages\django\template\loader.py", line 19, in get_template
    raise TemplateDoesNotExist(template_name, chain=chain)
django.template.exceptions.TemplateDoesNotExist: dashboard/driver_dashboard.html
Internal Server Error: /dashboard/driver/
Traceback (most recent call last):
  File "D:\Dev\fuelmng\venv\Lib\site-packages\django\core\handlers\exception.py", line 55, in inner
    response = get_response(request)
               ^^^^^^^^^^^^^^^^^^^^^
  File "D:\Dev\fuelmng\venv\Lib\site-packages\django\core\handlers\base.py", line 197, in _get_response
    response = wrapped_callback(request, *callback_args, **callback_kwargs)
               ^^^^^^^^^^^^^^^^^^^^^^^^^^^^^^^^^^^^^^^^^^^^^^^^^^^^^^^^^^^^
  File "D:\Dev\fuelmng\venv\Lib\site-packages\django\contrib\auth\decorators.py", line 23, in _wrapper_view
    return view_func(request, *args, **kwargs)
           ^^^^^^^^^^^^^^^^^^^^^^^^^^^^^^^^^^^
  File "D:\Dev\fuelmng\dashboard\views.py", line 96, in driver_dashboard
    return render(request, 'dashboard/driver_dashboard.html', context)
           ^^^^^^^^^^^^^^^^^^^^^^^^^^^^^^^^^^^^^^^^^^^^^^^^^^^^^^^^^^^
  File "D:\Dev\fuelmng\venv\Lib\site-packages\django\shortcuts.py", line 24, in render
    content = loader.render_to_string(template_name, context, request, using=using)
              ^^^^^^^^^^^^^^^^^^^^^^^^^^^^^^^^^^^^^^^^^^^^^^^^^^^^^^^^^^^^^^^^^^^^^
  File "D:\Dev\fuelmng\venv\Lib\site-packages\django\template\loader.py", line 61, in render_to_string
    template = get_template(template_name, using=using)
               ^^^^^^^^^^^^^^^^^^^^^^^^^^^^^^^^^^^^^^^^
  File "D:\Dev\fuelmng\venv\Lib\site-packages\django\template\loader.py", line 19, in get_template
    raise TemplateDoesNotExist(template_name, chain=chain)
django.template.exceptions.TemplateDoesNotExist: dashboard/driver_dashboard.html
Not Found: /favicon.ico
Internal Server Error: /dashboard/driver/
Traceback (most recent call last):
  File "D:\Dev\fuelmng\venv\Lib\site-packages\django\core\handlers\exception.py", line 55, in inner
    response = get_response(request)
               ^^^^^^^^^^^^^^^^^^^^^
  File "D:\Dev\fuelmng\venv\Lib\site-packages\django\core\handlers\base.py", line 197, in _get_response
    response = wrapped_callback(request, *callback_args, **callback_kwargs)
               ^^^^^^^^^^^^^^^^^^^^^^^^^^^^^^^^^^^^^^^^^^^^^^^^^^^^^^^^^^^^
  File "D:\Dev\fuelmng\venv\Lib\site-packages\django\contrib\auth\decorators.py", line 23, in _wrapper_view
    return view_func(request, *args, **kwargs)
           ^^^^^^^^^^^^^^^^^^^^^^^^^^^^^^^^^^^
  File "D:\Dev\fuelmng\dashboard\views.py", line 96, in driver_dashboard
    return render(request, 'dashboard/driver_dashboard.html', context)
           ^^^^^^^^^^^^^^^^^^^^^^^^^^^^^^^^^^^^^^^^^^^^^^^^^^^^^^^^^^^
  File "D:\Dev\fuelmng\venv\Lib\site-packages\django\shortcuts.py", line 24, in render
    content = loader.render_to_string(template_name, context, request, using=using)
              ^^^^^^^^^^^^^^^^^^^^^^^^^^^^^^^^^^^^^^^^^^^^^^^^^^^^^^^^^^^^^^^^^^^^^
  File "D:\Dev\fuelmng\venv\Lib\site-packages\django\template\loader.py", line 61, in render_to_string
    template = get_template(template_name, using=using)
               ^^^^^^^^^^^^^^^^^^^^^^^^^^^^^^^^^^^^^^^^
  File "D:\Dev\fuelmng\venv\Lib\site-packages\django\template\loader.py", line 19, in get_template
    raise TemplateDoesNotExist(template_name, chain=chain)
django.template.exceptions.TemplateDoesNotExist: dashboard/driver_dashboard.html
D:\Dev\fuelmng\fuel_management\settings.py changed, reloading.
Watching for file changes with StatReloader
Not Found: /favicon.ico
Not Found: /favicon.ico
Not Found: /api/mobile/vehicles/
Not Found: /api/mobile/vehicles/
Not Found: /dashboard/admin/
D:\Dev\fuelmng\dashboard\urls.py changed, reloading.
Watching for file changes with StatReloader
Watching for file changes with StatReloader
D:\Dev\fuelmng\fuel_management\settings.py changed, reloading.
Watching for file changes with StatReloader
Watching for file changes with StatReloader
D:\Dev\fuelmng\dashboard\views.py changed, reloading.
Watching for file changes with StatReloader
Watching for file changes with StatReloader
D:\Dev\fuelmng\dashboard\urls.py changed, reloading.
Watching for file changes with StatReloader
Watching for file changes with StatReloader
D:\Dev\fuelmng\dashboard\views.py changed, reloading.
Watching for file changes with StatReloader
Watching for file changes with StatReloader
Not Found: /api/mobile/vehicles/
Not Found: /accounts/login/
Not Found: /accounts/login/
Not Found: /accounts/login/
Not Found: /accounts/login/
D:\Dev\fuelmng\dashboard\urls.py changed, reloading.
Watching for file changes with StatReloader
D:\Dev\fuelmng\dashboard\views.py changed, reloading.
Watching for file changes with StatReloader
Not Found: /favicon.ico
Internal Server Error: /vehicles/create/
Traceback (most recent call last):
  File "D:\Dev\fuelmng\venv\Lib\site-packages\django\db\backends\utils.py", line 89, in _execute
    return self.cursor.execute(sql, params)
           ^^^^^^^^^^^^^^^^^^^^^^^^^^^^^^^^
  File "D:\Dev\fuelmng\venv\Lib\site-packages\psycopg\cursor.py", line 97, in execute
    raise ex.with_traceback(None)
psycopg.errors.NotNullViolation: null value in column "company_id" of relation "vehicles_vehicle" violates not-null constraint
DETAIL:  Failing row contains (1, RJ19YS6166, Honda, Scooty, 2017, gasoline, 5.50, 25.00, t, 2025-09-01 01:15:29.22535-05, 1, null).

The above exception was the direct cause of the following exception:

Traceback (most recent call last):
  File "D:\Dev\fuelmng\venv\Lib\site-packages\django\core\handlers\exception.py", line 55, in inner
    response = get_response(request)
               ^^^^^^^^^^^^^^^^^^^^^
  File "D:\Dev\fuelmng\venv\Lib\site-packages\django\core\handlers\base.py", line 197, in _get_response
    response = wrapped_callback(request, *callback_args, **callback_kwargs)
               ^^^^^^^^^^^^^^^^^^^^^^^^^^^^^^^^^^^^^^^^^^^^^^^^^^^^^^^^^^^^
  File "D:\Dev\fuelmng\venv\Lib\site-packages\django\contrib\auth\decorators.py", line 23, in _wrapper_view
    return view_func(request, *args, **kwargs)
           ^^^^^^^^^^^^^^^^^^^^^^^^^^^^^^^^^^^
  File "D:\Dev\fuelmng\dashboard\views.py", line 159, in vehicle_create
    vehicle.save()
  File "D:\Dev\fuelmng\venv\Lib\site-packages\django\db\models\base.py", line 814, in save
    self.save_base(
  File "D:\Dev\fuelmng\venv\Lib\site-packages\django\db\models\base.py", line 877, in save_base
    updated = self._save_table(
              ^^^^^^^^^^^^^^^^^
  File "D:\Dev\fuelmng\venv\Lib\site-packages\django\db\models\base.py", line 1020, in _save_table
    results = self._do_insert(
              ^^^^^^^^^^^^^^^^
  File "D:\Dev\fuelmng\venv\Lib\site-packages\django\db\models\base.py", line 1061, in _do_insert
    return manager._insert(
           ^^^^^^^^^^^^^^^^
  File "D:\Dev\fuelmng\venv\Lib\site-packages\django\db\models\manager.py", line 87, in manager_method
    return getattr(self.get_queryset(), name)(*args, **kwargs)
           ^^^^^^^^^^^^^^^^^^^^^^^^^^^^^^^^^^^^^^^^^^^^^^^^^^^
  File "D:\Dev\fuelmng\venv\Lib\site-packages\django\db\models\query.py", line 1805, in _insert
    return query.get_compiler(using=using).execute_sql(returning_fields)
           ^^^^^^^^^^^^^^^^^^^^^^^^^^^^^^^^^^^^^^^^^^^^^^^^^^^^^^^^^^^^^
  File "D:\Dev\fuelmng\venv\Lib\site-packages\django\db\models\sql\compiler.py", line 1822, in execute_sql
    cursor.execute(sql, params)
  File "D:\Dev\fuelmng\venv\Lib\site-packages\django\db\backends\utils.py", line 102, in execute
    return super().execute(sql, params)
           ^^^^^^^^^^^^^^^^^^^^^^^^^^^^
  File "D:\Dev\fuelmng\venv\Lib\site-packages\django\db\backends\utils.py", line 67, in execute
    return self._execute_with_wrappers(
           ^^^^^^^^^^^^^^^^^^^^^^^^^^^^
  File "D:\Dev\fuelmng\venv\Lib\site-packages\django\db\backends\utils.py", line 80, in _execute_with_wrappers
    return executor(sql, params, many, context)
           ^^^^^^^^^^^^^^^^^^^^^^^^^^^^^^^^^^^^
  File "D:\Dev\fuelmng\venv\Lib\site-packages\django\db\backends\utils.py", line 84, in _execute
    with self.db.wrap_database_errors:
  File "D:\Dev\fuelmng\venv\Lib\site-packages\django\db\utils.py", line 91, in __exit__
    raise dj_exc_value.with_traceback(traceback) from exc_value
  File "D:\Dev\fuelmng\venv\Lib\site-packages\django\db\backends\utils.py", line 89, in _execute
    return self.cursor.execute(sql, params)
           ^^^^^^^^^^^^^^^^^^^^^^^^^^^^^^^^
  File "D:\Dev\fuelmng\venv\Lib\site-packages\psycopg\cursor.py", line 97, in execute
    raise ex.with_traceback(None)
django.db.utils.IntegrityError: null value in column "company_id" of relation "vehicles_vehicle" violates not-null constraint
DETAIL:  Failing row contains (1, RJ19YS6166, Honda, Scooty, 2017, gasoline, 5.50, 25.00, t, 2025-09-01 01:15:29.22535-05, 1, null).
D:\Dev\fuelmng\dashboard\views.py changed, reloading.
Watching for file changes with StatReloader
Watching for file changes with StatReloader
D:\Dev\fuelmng\dashboard\forms.py changed, reloading.
Watching for file changes with StatReloader
Not Found: /favicon.ico
D:\Dev\fuelmng\dashboard\views.py changed, reloading.
Watching for file changes with StatReloader
D:\Dev\fuelmng\dashboard\forms.py changed, reloading.
Watching for file changes with StatReloader
Internal Server Error: /vehicles/create/
Traceback (most recent call last):
  File "D:\Dev\fuelmng\venv\Lib\site-packages\django\db\models\query.py", line 916, in get_or_create
    return self.get(**kwargs), False
           ^^^^^^^^^^^^^^^^^^
  File "D:\Dev\fuelmng\venv\Lib\site-packages\django\db\models\query.py", line 637, in get
    raise self.model.DoesNotExist(
accounts.models.Company.DoesNotExist: Company matching query does not exist.

During handling of the above exception, another exception occurred:

Traceback (most recent call last):
  File "D:\Dev\fuelmng\venv\Lib\site-packages\django\core\handlers\exception.py", line 55, in inner
    response = get_response(request)
               ^^^^^^^^^^^^^^^^^^^^^
  File "D:\Dev\fuelmng\venv\Lib\site-packages\django\core\handlers\base.py", line 197, in _get_response
    response = wrapped_callback(request, *callback_args, **callback_kwargs)
               ^^^^^^^^^^^^^^^^^^^^^^^^^^^^^^^^^^^^^^^^^^^^^^^^^^^^^^^^^^^^
  File "D:\Dev\fuelmng\venv\Lib\site-packages\django\contrib\auth\decorators.py", line 23, in _wrapper_view
    return view_func(request, *args, **kwargs)
           ^^^^^^^^^^^^^^^^^^^^^^^^^^^^^^^^^^^
  File "D:\Dev\fuelmng\dashboard\views.py", line 163, in vehicle_create
    user_company, created = Company.objects.get_or_create(
                            ^^^^^^^^^^^^^^^^^^^^^^^^^^^^^^
  File "D:\Dev\fuelmng\venv\Lib\site-packages\django\db\models\manager.py", line 87, in manager_method
    return getattr(self.get_queryset(), name)(*args, **kwargs)
           ^^^^^^^^^^^^^^^^^^^^^^^^^^^^^^^^^^^^^^^^^^^^^^^^^^^
  File "D:\Dev\fuelmng\venv\Lib\site-packages\django\db\models\query.py", line 918, in get_or_create
    params = self._extract_model_params(defaults, **kwargs)
             ^^^^^^^^^^^^^^^^^^^^^^^^^^^^^^^^^^^^^^^^^^^^^^
  File "D:\Dev\fuelmng\venv\Lib\site-packages\django\db\models\query.py", line 999, in _extract_model_params
    raise exceptions.FieldError(
django.core.exceptions.FieldError: Invalid field name(s) for model Company: 'description'.
D:\Dev\fuelmng\dashboard\views.py changed, reloading.
Watching for file changes with StatReloader
Not Found: /api/mobile/vehicles/
Not Found: /api/mobile/vehicles/
Not Found: /api/mobile/vehicles/
D:\Dev\fuelmng\mobile_api\views.py changed, reloading.
Watching for file changes with StatReloader
Watching for file changes with StatReloader
D:\Dev\fuelmng\mobile_api\views.py changed, reloading.
Watching for file changes with StatReloader
D:\Dev\fuelmng\mobile_api\urls.py changed, reloading.
Watching for file changes with StatReloader
Watching for file changes with StatReloader
D:\Dev\fuelmng\fuel_management\settings.py changed, reloading.
Watching for file changes with StatReloader
D:\Dev\fuelmng\mobile_api\views.py changed, reloading.
Watching for file changes with StatReloader
D:\Dev\fuelmng\fuel_management\urls.py changed, reloading.
Watching for file changes with StatReloader
D:\Dev\fuelmng\mobile_api\views.py changed, reloading.
Watching for file changes with StatReloader
Forbidden (CSRF cookie not set.): /mobile/upload/
D:\Dev\fuelmng\mobile_api\views.py changed, reloading.
Watching for file changes with StatReloader
D:\Dev\fuelmng\mobile_api\views.py changed, reloading.
Watching for file changes with StatReloader
D:\Dev\fuelmng\mobile_api\urls.py changed, reloading.
Watching for file changes with StatReloader
D:\Dev\fuelmng\mobile_api\views.py changed, reloading.
Watching for file changes with StatReloader
D:\Dev\fuelmng\mobile_api\views.py changed, reloading.
Watching for file changes with StatReloader
D:\Dev\fuelmng\mobile_api\views.py changed, reloading.
Watching for file changes with StatReloader
D:\Dev\fuelmng\mobile_api\views.py changed, reloading.
Watching for file changes with StatReloader
D:\Dev\fuelmng\receipts\models.py changed, reloading.
Watching for file changes with StatReloader
Gemini test response: API connection successful

Processing receipt #1 with Gemini API...
Sending request to Gemini API for receipt #1...
Receipt #1 processed successfully: total=20000.0 gallons=218.364 station=Indian Oil
Internal Server Error: /dashboard/admin/
Traceback (most recent call last):
  File "D:\Dev\fuelmng\venv\Lib\site-packages\django\core\handlers\exception.py", line 55, in inner
    response = get_response(request)
               ^^^^^^^^^^^^^^^^^^^^^
  File "D:\Dev\fuelmng\venv\Lib\site-packages\django\core\handlers\base.py", line 197, in _get_response
    response = wrapped_callback(request, *callback_args, **callback_kwargs)
               ^^^^^^^^^^^^^^^^^^^^^^^^^^^^^^^^^^^^^^^^^^^^^^^^^^^^^^^^^^^^
  File "D:\Dev\fuelmng\venv\Lib\site-packages\django\contrib\auth\decorators.py", line 23, in _wrapper_view
    return view_func(request, *args, **kwargs)
           ^^^^^^^^^^^^^^^^^^^^^^^^^^^^^^^^^^^
  File "D:\Dev\fuelmng\dashboard\views.py", line 52, in dashboard_view
    recent_receipts_qs = FuelReceipt.objects.filter(
                         ^^^^^^^^^^^^^^^^^^^^^^^^^^^
  File "D:\Dev\fuelmng\venv\Lib\site-packages\django\db\models\manager.py", line 87, in manager_method
    return getattr(self.get_queryset(), name)(*args, **kwargs)
           ^^^^^^^^^^^^^^^^^^^^^^^^^^^^^^^^^^^^^^^^^^^^^^^^^^^
  File "D:\Dev\fuelmng\venv\Lib\site-packages\django\db\models\query.py", line 1436, in filter
    return self._filter_or_exclude(False, args, kwargs)
           ^^^^^^^^^^^^^^^^^^^^^^^^^^^^^^^^^^^^^^^^^^^^
  File "D:\Dev\fuelmng\venv\Lib\site-packages\django\db\models\query.py", line 1454, in _filter_or_exclude
    clone._filter_or_exclude_inplace(negate, args, kwargs)
  File "D:\Dev\fuelmng\venv\Lib\site-packages\django\db\models\query.py", line 1461, in _filter_or_exclude_inplace
    self._query.add_q(Q(*args, **kwargs))
  File "D:\Dev\fuelmng\venv\Lib\site-packages\django\db\models\sql\query.py", line 1545, in add_q
    clause, _ = self._add_q(q_object, self.used_aliases)
                ^^^^^^^^^^^^^^^^^^^^^^^^^^^^^^^^^^^^^^^^
  File "D:\Dev\fuelmng\venv\Lib\site-packages\django\db\models\sql\query.py", line 1576, in _add_q
    child_clause, needed_inner = self.build_filter(
                                 ^^^^^^^^^^^^^^^^^^
  File "D:\Dev\fuelmng\venv\Lib\site-packages\django\db\models\sql\query.py", line 1426, in build_filter
    lookups, parts, reffed_expression = self.solve_lookup_type(arg, summarize)
                                        ^^^^^^^^^^^^^^^^^^^^^^^^^^^^^^^^^^^^^^
  File "D:\Dev\fuelmng\venv\Lib\site-packages\django\db\models\sql\query.py", line 1236, in solve_lookup_type
    _, field, _, lookup_parts = self.names_to_path(lookup_splitted, self.get_meta())
                                ^^^^^^^^^^^^^^^^^^^^^^^^^^^^^^^^^^^^^^^^^^^^^^^^^^^^
  File "D:\Dev\fuelmng\venv\Lib\site-packages\django\db\models\sql\query.py", line 1724, in names_to_path
    raise FieldError(
django.core.exceptions.FieldError: Cannot resolve keyword 'transaction_date' into field. Choices are: company, company_id, confidence_score, created_at, driver, driver_id, gallons, id, price_per_gallon, processing_status, raw_ocr_text, receipt_image, station_address, station_name, total_amount, updated_at, vehicle, vehicle_id
Internal Server Error: /dashboard/admin/
Traceback (most recent call last):
  File "D:\Dev\fuelmng\venv\Lib\site-packages\django\core\handlers\exception.py", line 55, in inner
    response = get_response(request)
               ^^^^^^^^^^^^^^^^^^^^^
  File "D:\Dev\fuelmng\venv\Lib\site-packages\django\core\handlers\base.py", line 197, in _get_response
    response = wrapped_callback(request, *callback_args, **callback_kwargs)
               ^^^^^^^^^^^^^^^^^^^^^^^^^^^^^^^^^^^^^^^^^^^^^^^^^^^^^^^^^^^^
  File "D:\Dev\fuelmng\venv\Lib\site-packages\django\contrib\auth\decorators.py", line 23, in _wrapper_view
    return view_func(request, *args, **kwargs)
           ^^^^^^^^^^^^^^^^^^^^^^^^^^^^^^^^^^^
  File "D:\Dev\fuelmng\dashboard\views.py", line 52, in dashboard_view
    recent_receipts_qs = FuelReceipt.objects.filter(
                         ^^^^^^^^^^^^^^^^^^^^^^^^^^^
  File "D:\Dev\fuelmng\venv\Lib\site-packages\django\db\models\manager.py", line 87, in manager_method
    return getattr(self.get_queryset(), name)(*args, **kwargs)
           ^^^^^^^^^^^^^^^^^^^^^^^^^^^^^^^^^^^^^^^^^^^^^^^^^^^
  File "D:\Dev\fuelmng\venv\Lib\site-packages\django\db\models\query.py", line 1436, in filter
    return self._filter_or_exclude(False, args, kwargs)
           ^^^^^^^^^^^^^^^^^^^^^^^^^^^^^^^^^^^^^^^^^^^^
  File "D:\Dev\fuelmng\venv\Lib\site-packages\django\db\models\query.py", line 1454, in _filter_or_exclude
    clone._filter_or_exclude_inplace(negate, args, kwargs)
  File "D:\Dev\fuelmng\venv\Lib\site-packages\django\db\models\query.py", line 1461, in _filter_or_exclude_inplace
    self._query.add_q(Q(*args, **kwargs))
  File "D:\Dev\fuelmng\venv\Lib\site-packages\django\db\models\sql\query.py", line 1545, in add_q
    clause, _ = self._add_q(q_object, self.used_aliases)
                ^^^^^^^^^^^^^^^^^^^^^^^^^^^^^^^^^^^^^^^^
  File "D:\Dev\fuelmng\venv\Lib\site-packages\django\db\models\sql\query.py", line 1576, in _add_q
    child_clause, needed_inner = self.build_filter(
                                 ^^^^^^^^^^^^^^^^^^
  File "D:\Dev\fuelmng\venv\Lib\site-packages\django\db\models\sql\query.py", line 1426, in build_filter
    lookups, parts, reffed_expression = self.solve_lookup_type(arg, summarize)
                                        ^^^^^^^^^^^^^^^^^^^^^^^^^^^^^^^^^^^^^^
  File "D:\Dev\fuelmng\venv\Lib\site-packages\django\db\models\sql\query.py", line 1236, in solve_lookup_type
    _, field, _, lookup_parts = self.names_to_path(lookup_splitted, self.get_meta())
                                ^^^^^^^^^^^^^^^^^^^^^^^^^^^^^^^^^^^^^^^^^^^^^^^^^^^^
  File "D:\Dev\fuelmng\venv\Lib\site-packages\django\db\models\sql\query.py", line 1724, in names_to_path
    raise FieldError(
django.core.exceptions.FieldError: Cannot resolve keyword 'transaction_date' into field. Choices are: company, company_id, confidence_score, created_at, driver, driver_id, gallons, id, price_per_gallon, processing_status, raw_ocr_text, receipt_image, station_address, station_name, total_amount, updated_at, vehicle, vehicle_id
Watching for file changes with StatReloader
Watching for file changes with StatReloader
Watching for file changes with StatReloader
Watching for file changes with StatReloader
Watching for file changes with StatReloader
Watching for file changes with StatReloader
Watching for file changes with StatReloader
D:\Dev\fuelmng\dashboard\views.py changed, reloading.
Watching for file changes with StatReloader
D:\Dev\fuelmng\vehicles\models.py changed, reloading.
Watching for file changes with StatReloader
D:\Dev\fuelmng\vehicles\migrations\0001_initial.py changed, reloading.
Watching for file changes with StatReloader
D:\Dev\fuelmng\mobile_api\views.py changed, reloading.
Watching for file changes with StatReloader
D:\Dev\fuelmng\receipts\models.py changed, reloading.
Watching for file changes with StatReloader
Watching for file changes with StatReloader
Not Found: /.well-known/appspecific/com.chrome.devtools.json
Not Found: /vehicles/3/delete/
Not Found: /vehicles/2/delete/
D:\Dev\fuelmng\mobile_api\views.py changed, reloading.
Watching for file changes with StatReloader
D:\Dev\fuelmng\receipts\models.py changed, reloading.
Watching for file changes with StatReloader
Watching for file changes with StatReloader
Processing receipt #16 with Gemini API...
Sending request to Gemini API for receipt #16...
Receipt #16 processed successfully: total=20000.0 gallons=218364.0 station=Indian Oil
D:\Dev\fuelmng\dashboard\views.py changed, reloading.
Watching for file changes with StatReloader
Not Found: /dashboard/analytics-data/
Not Found: /dashboard/analytics-data/
Not Found: /.well-known/appspecific/com.chrome.devtools.json
D:\Dev\fuelmng\dashboard\views.py changed, reloading.
Watching for file changes with StatReloader
D:\Dev\fuelmng\dashboard\urls.py changed, reloading.
Watching for file changes with StatReloader
Not Found: /.well-known/appspecific/com.chrome.devtools.json
Processing receipt #17 with Gemini API...
Sending request to Gemini API for receipt #17...
Receipt #17 processed successfully: total=20000.0 gallons=218364.0 station=IndianOil
Not Found: /.well-known/appspecific/com.chrome.devtools.json
Not Found: /.well-known/appspecific/com.chrome.devtools.json
Not Found: /.well-known/appspecific/com.chrome.devtools.json
Watching for file changes with StatReloader
Internal Server Error: /
Traceback (most recent call last):
  File "C:\Users\owesh\AppData\Local\Programs\Python\Python312\Lib\site-packages\django\core\handlers\exception.py", line 55, in inner
    response = get_response(request)
               ^^^^^^^^^^^^^^^^^^^^^
  File "C:\Users\owesh\AppData\Local\Programs\Python\Python312\Lib\site-packages\django\core\handlers\base.py", line 197, in _get_response
    response = wrapped_callback(request, *callback_args, **callback_kwargs)
               ^^^^^^^^^^^^^^^^^^^^^^^^^^^^^^^^^^^^^^^^^^^^^^^^^^^^^^^^^^^^
  File "C:\Users\owesh\AppData\Local\Programs\Python\Python312\Lib\site-packages\django\utils\decorators.py", line 134, in _wrapper_view
    response = view_func(request, *args, **kwargs)
               ^^^^^^^^^^^^^^^^^^^^^^^^^^^^^^^^^^^
  File "D:\Dev\fuelmng\accounts\views.py", line 65, in login_register_view
    return render(request, 'auth/login_register.html', context)
           ^^^^^^^^^^^^^^^^^^^^^^^^^^^^^^^^^^^^^^^^^^^^^^^^^^^^
  File "C:\Users\owesh\AppData\Local\Programs\Python\Python312\Lib\site-packages\django\shortcuts.py", line 24, in render
    content = loader.render_to_string(template_name, context, request, using=using)
              ^^^^^^^^^^^^^^^^^^^^^^^^^^^^^^^^^^^^^^^^^^^^^^^^^^^^^^^^^^^^^^^^^^^^^
  File "C:\Users\owesh\AppData\Local\Programs\Python\Python312\Lib\site-packages\django\template\loader.py", line 62, in render_to_string
    return template.render(context, request)
           ^^^^^^^^^^^^^^^^^^^^^^^^^^^^^^^^^
  File "C:\Users\owesh\AppData\Local\Programs\Python\Python312\Lib\site-packages\django\template\backends\django.py", line 61, in render
    return self.template.render(context)
           ^^^^^^^^^^^^^^^^^^^^^^^^^^^^^
  File "C:\Users\owesh\AppData\Local\Programs\Python\Python312\Lib\site-packages\django\template\base.py", line 175, in render
    return self._render(context)
           ^^^^^^^^^^^^^^^^^^^^^
  File "C:\Users\owesh\AppData\Local\Programs\Python\Python312\Lib\site-packages\django\template\base.py", line 167, in _render
    return self.nodelist.render(context)
           ^^^^^^^^^^^^^^^^^^^^^^^^^^^^^
  File "C:\Users\owesh\AppData\Local\Programs\Python\Python312\Lib\site-packages\django\template\base.py", line 1005, in render
    return SafeString("".join([node.render_annotated(context) for node in self]))
                               ^^^^^^^^^^^^^^^^^^^^^^^^^^^^^^
  File "C:\Users\owesh\AppData\Local\Programs\Python\Python312\Lib\site-packages\django\template\base.py", line 966, in render_annotated
    return self.render(context)
           ^^^^^^^^^^^^^^^^^^^^
  File "C:\Users\owesh\AppData\Local\Programs\Python\Python312\Lib\site-packages\django\template\defaulttags.py", line 471, in render
    url = reverse(view_name, args=args, kwargs=kwargs, current_app=current_app)
          ^^^^^^^^^^^^^^^^^^^^^^^^^^^^^^^^^^^^^^^^^^^^^^^^^^^^^^^^^^^^^^^^^^^^^
  File "C:\Users\owesh\AppData\Local\Programs\Python\Python312\Lib\site-packages\django\urls\base.py", line 88, in reverse
    return resolver._reverse_with_prefix(view, prefix, *args, **kwargs)
           ^^^^^^^^^^^^^^^^^^^^^^^^^^^^^^^^^^^^^^^^^^^^^^^^^^^^^^^^^^^^
  File "C:\Users\owesh\AppData\Local\Programs\Python\Python312\Lib\site-packages\django\urls\resolvers.py", line 828, in _reverse_with_prefix
    raise NoReverseMatch(msg)
django.urls.exceptions.NoReverseMatch: Reverse for 'login' not found. 'login' is not a valid view function or pattern name.
Internal Server Error: /
Traceback (most recent call last):
  File "C:\Users\owesh\AppData\Local\Programs\Python\Python312\Lib\site-packages\django\core\handlers\exception.py", line 55, in inner
    response = get_response(request)
               ^^^^^^^^^^^^^^^^^^^^^
  File "C:\Users\owesh\AppData\Local\Programs\Python\Python312\Lib\site-packages\django\core\handlers\base.py", line 197, in _get_response
    response = wrapped_callback(request, *callback_args, **callback_kwargs)
               ^^^^^^^^^^^^^^^^^^^^^^^^^^^^^^^^^^^^^^^^^^^^^^^^^^^^^^^^^^^^
  File "C:\Users\owesh\AppData\Local\Programs\Python\Python312\Lib\site-packages\django\utils\decorators.py", line 134, in _wrapper_view
    response = view_func(request, *args, **kwargs)
               ^^^^^^^^^^^^^^^^^^^^^^^^^^^^^^^^^^^
  File "D:\Dev\fuelmng\accounts\views.py", line 65, in login_register_view
    return render(request, 'auth/login_register.html', context)
           ^^^^^^^^^^^^^^^^^^^^^^^^^^^^^^^^^^^^^^^^^^^^^^^^^^^^
  File "C:\Users\owesh\AppData\Local\Programs\Python\Python312\Lib\site-packages\django\shortcuts.py", line 24, in render
    content = loader.render_to_string(template_name, context, request, using=using)
              ^^^^^^^^^^^^^^^^^^^^^^^^^^^^^^^^^^^^^^^^^^^^^^^^^^^^^^^^^^^^^^^^^^^^^
  File "C:\Users\owesh\AppData\Local\Programs\Python\Python312\Lib\site-packages\django\template\loader.py", line 62, in render_to_string
    return template.render(context, request)
           ^^^^^^^^^^^^^^^^^^^^^^^^^^^^^^^^^
  File "C:\Users\owesh\AppData\Local\Programs\Python\Python312\Lib\site-packages\django\template\backends\django.py", line 61, in render
    return self.template.render(context)
           ^^^^^^^^^^^^^^^^^^^^^^^^^^^^^
  File "C:\Users\owesh\AppData\Local\Programs\Python\Python312\Lib\site-packages\django\template\base.py", line 175, in render
    return self._render(context)
           ^^^^^^^^^^^^^^^^^^^^^
  File "C:\Users\owesh\AppData\Local\Programs\Python\Python312\Lib\site-packages\django\template\base.py", line 167, in _render
    return self.nodelist.render(context)
           ^^^^^^^^^^^^^^^^^^^^^^^^^^^^^
  File "C:\Users\owesh\AppData\Local\Programs\Python\Python312\Lib\site-packages\django\template\base.py", line 1005, in render
    return SafeString("".join([node.render_annotated(context) for node in self]))
                               ^^^^^^^^^^^^^^^^^^^^^^^^^^^^^^
  File "C:\Users\owesh\AppData\Local\Programs\Python\Python312\Lib\site-packages\django\template\base.py", line 966, in render_annotated
    return self.render(context)
           ^^^^^^^^^^^^^^^^^^^^
  File "C:\Users\owesh\AppData\Local\Programs\Python\Python312\Lib\site-packages\django\template\defaulttags.py", line 471, in render
    url = reverse(view_name, args=args, kwargs=kwargs, current_app=current_app)
          ^^^^^^^^^^^^^^^^^^^^^^^^^^^^^^^^^^^^^^^^^^^^^^^^^^^^^^^^^^^^^^^^^^^^^
  File "C:\Users\owesh\AppData\Local\Programs\Python\Python312\Lib\site-packages\django\urls\base.py", line 88, in reverse
    return resolver._reverse_with_prefix(view, prefix, *args, **kwargs)
           ^^^^^^^^^^^^^^^^^^^^^^^^^^^^^^^^^^^^^^^^^^^^^^^^^^^^^^^^^^^^
  File "C:\Users\owesh\AppData\Local\Programs\Python\Python312\Lib\site-packages\django\urls\resolvers.py", line 828, in _reverse_with_prefix
    raise NoReverseMatch(msg)
django.urls.exceptions.NoReverseMatch: Reverse for 'login' not found. 'login' is not a valid view function or pattern name.
Not Found: /favicon.ico
Not Found: /favicon.ico
Internal Server Error: /
Traceback (most recent call last):
  File "C:\Users\owesh\AppData\Local\Programs\Python\Python312\Lib\site-packages\django\core\handlers\exception.py", line 55, in inner
    response = get_response(request)
               ^^^^^^^^^^^^^^^^^^^^^
  File "C:\Users\owesh\AppData\Local\Programs\Python\Python312\Lib\site-packages\django\core\handlers\base.py", line 197, in _get_response
    response = wrapped_callback(request, *callback_args, **callback_kwargs)
               ^^^^^^^^^^^^^^^^^^^^^^^^^^^^^^^^^^^^^^^^^^^^^^^^^^^^^^^^^^^^
  File "C:\Users\owesh\AppData\Local\Programs\Python\Python312\Lib\site-packages\django\utils\decorators.py", line 134, in _wrapper_view
    response = view_func(request, *args, **kwargs)
               ^^^^^^^^^^^^^^^^^^^^^^^^^^^^^^^^^^^
  File "D:\Dev\fuelmng\accounts\views.py", line 65, in login_register_view
    return render(request, 'auth/login_register.html', context)
           ^^^^^^^^^^^^^^^^^^^^^^^^^^^^^^^^^^^^^^^^^^^^^^^^^^^^
  File "C:\Users\owesh\AppData\Local\Programs\Python\Python312\Lib\site-packages\django\shortcuts.py", line 24, in render
    content = loader.render_to_string(template_name, context, request, using=using)
              ^^^^^^^^^^^^^^^^^^^^^^^^^^^^^^^^^^^^^^^^^^^^^^^^^^^^^^^^^^^^^^^^^^^^^
  File "C:\Users\owesh\AppData\Local\Programs\Python\Python312\Lib\site-packages\django\template\loader.py", line 62, in render_to_string
    return template.render(context, request)
           ^^^^^^^^^^^^^^^^^^^^^^^^^^^^^^^^^
  File "C:\Users\owesh\AppData\Local\Programs\Python\Python312\Lib\site-packages\django\template\backends\django.py", line 61, in render
    return self.template.render(context)
           ^^^^^^^^^^^^^^^^^^^^^^^^^^^^^
  File "C:\Users\owesh\AppData\Local\Programs\Python\Python312\Lib\site-packages\django\template\base.py", line 175, in render
    return self._render(context)
           ^^^^^^^^^^^^^^^^^^^^^
  File "C:\Users\owesh\AppData\Local\Programs\Python\Python312\Lib\site-packages\django\template\base.py", line 167, in _render
    return self.nodelist.render(context)
           ^^^^^^^^^^^^^^^^^^^^^^^^^^^^^
  File "C:\Users\owesh\AppData\Local\Programs\Python\Python312\Lib\site-packages\django\template\base.py", line 1005, in render
    return SafeString("".join([node.render_annotated(context) for node in self]))
                               ^^^^^^^^^^^^^^^^^^^^^^^^^^^^^^
  File "C:\Users\owesh\AppData\Local\Programs\Python\Python312\Lib\site-packages\django\template\base.py", line 966, in render_annotated
    return self.render(context)
           ^^^^^^^^^^^^^^^^^^^^
  File "C:\Users\owesh\AppData\Local\Programs\Python\Python312\Lib\site-packages\django\template\defaulttags.py", line 471, in render
    url = reverse(view_name, args=args, kwargs=kwargs, current_app=current_app)
          ^^^^^^^^^^^^^^^^^^^^^^^^^^^^^^^^^^^^^^^^^^^^^^^^^^^^^^^^^^^^^^^^^^^^^
  File "C:\Users\owesh\AppData\Local\Programs\Python\Python312\Lib\site-packages\django\urls\base.py", line 88, in reverse
    return resolver._reverse_with_prefix(view, prefix, *args, **kwargs)
           ^^^^^^^^^^^^^^^^^^^^^^^^^^^^^^^^^^^^^^^^^^^^^^^^^^^^^^^^^^^^
  File "C:\Users\owesh\AppData\Local\Programs\Python\Python312\Lib\site-packages\django\urls\resolvers.py", line 828, in _reverse_with_prefix
    raise NoReverseMatch(msg)
django.urls.exceptions.NoReverseMatch: Reverse for 'login' not found. 'login' is not a valid view function or pattern name.
D:\Dev\fuelmng\accounts\urls.py changed, reloading.
Watching for file changes with StatReloader
D:\Dev\fuelmng\accounts\views.py changed, reloading.
Watching for file changes with StatReloader
Internal Server Error: /register/
Traceback (most recent call last):
  File "C:\Users\owesh\AppData\Local\Programs\Python\Python312\Lib\site-packages\django\db\backends\utils.py", line 89, in _execute
    return self.cursor.execute(sql, params)
           ^^^^^^^^^^^^^^^^^^^^^^^^^^^^^^^^
  File "C:\Users\owesh\AppData\Local\Programs\Python\Python312\Lib\site-packages\psycopg\cursor.py", line 97, in execute
    raise ex.with_traceback(None)
psycopg.errors.NotNullViolation: null value in column "phone" of relation "accounts_customuser" violates not-null constraint
DETAIL:  Failing row contains (2, pbkdf2_sha256$600000$bpGHxzoYeSe5q3eItOPHpr$8/apUtUML4v/fpECxWcW..., null, f, owesh, owesh, khan, oweshkhan96@gmail.com, t, t, 2025-09-01 23:55:44.350671-05, admin, null, null).

The above exception was the direct cause of the following exception:

Traceback (most recent call last):
  File "C:\Users\owesh\AppData\Local\Programs\Python\Python312\Lib\site-packages\django\core\handlers\exception.py", line 55, in inner
    response = get_response(request)
               ^^^^^^^^^^^^^^^^^^^^^
  File "C:\Users\owesh\AppData\Local\Programs\Python\Python312\Lib\site-packages\django\core\handlers\base.py", line 197, in _get_response
    response = wrapped_callback(request, *callback_args, **callback_kwargs)
               ^^^^^^^^^^^^^^^^^^^^^^^^^^^^^^^^^^^^^^^^^^^^^^^^^^^^^^^^^^^^
  File "C:\Users\owesh\AppData\Local\Programs\Python\Python312\Lib\site-packages\django\utils\decorators.py", line 134, in _wrapper_view
    response = view_func(request, *args, **kwargs)
               ^^^^^^^^^^^^^^^^^^^^^^^^^^^^^^^^^^^
  File "D:\Dev\fuelmng\accounts\views.py", line 41, in login_register_view
    user = form.save()
           ^^^^^^^^^^^
  File "D:\Dev\fuelmng\accounts\forms.py", line 28, in save
    user.save()
  File "C:\Users\owesh\AppData\Local\Programs\Python\Python312\Lib\site-packages\django\contrib\auth\base_user.py", line 76, in save
    super().save(*args, **kwargs)
  File "C:\Users\owesh\AppData\Local\Programs\Python\Python312\Lib\site-packages\django\db\models\base.py", line 814, in save
    self.save_base(
  File "C:\Users\owesh\AppData\Local\Programs\Python\Python312\Lib\site-packages\django\db\models\base.py", line 877, in save_base
    updated = self._save_table(
              ^^^^^^^^^^^^^^^^^
  File "C:\Users\owesh\AppData\Local\Programs\Python\Python312\Lib\site-packages\django\db\models\base.py", line 1020, in _save_table
    results = self._do_insert(
              ^^^^^^^^^^^^^^^^
  File "C:\Users\owesh\AppData\Local\Programs\Python\Python312\Lib\site-packages\django\db\models\base.py", line 1061, in _do_insert
    return manager._insert(
           ^^^^^^^^^^^^^^^^
  File "C:\Users\owesh\AppData\Local\Programs\Python\Python312\Lib\site-packages\django\db\models\manager.py", line 87, in manager_method
    return getattr(self.get_queryset(), name)(*args, **kwargs)
           ^^^^^^^^^^^^^^^^^^^^^^^^^^^^^^^^^^^^^^^^^^^^^^^^^^^
  File "C:\Users\owesh\AppData\Local\Programs\Python\Python312\Lib\site-packages\django\db\models\query.py", line 1805, in _insert
    return query.get_compiler(using=using).execute_sql(returning_fields)
           ^^^^^^^^^^^^^^^^^^^^^^^^^^^^^^^^^^^^^^^^^^^^^^^^^^^^^^^^^^^^^
  File "C:\Users\owesh\AppData\Local\Programs\Python\Python312\Lib\site-packages\django\db\models\sql\compiler.py", line 1822, in execute_sql
    cursor.execute(sql, params)
  File "C:\Users\owesh\AppData\Local\Programs\Python\Python312\Lib\site-packages\django\db\backends\utils.py", line 102, in execute
    return super().execute(sql, params)
           ^^^^^^^^^^^^^^^^^^^^^^^^^^^^
  File "C:\Users\owesh\AppData\Local\Programs\Python\Python312\Lib\site-packages\django\db\backends\utils.py", line 67, in execute
    return self._execute_with_wrappers(
           ^^^^^^^^^^^^^^^^^^^^^^^^^^^^
  File "C:\Users\owesh\AppData\Local\Programs\Python\Python312\Lib\site-packages\django\db\backends\utils.py", line 80, in _execute_with_wrappers
    return executor(sql, params, many, context)
           ^^^^^^^^^^^^^^^^^^^^^^^^^^^^^^^^^^^^
  File "C:\Users\owesh\AppData\Local\Programs\Python\Python312\Lib\site-packages\django\db\backends\utils.py", line 84, in _execute
    with self.db.wrap_database_errors:
  File "C:\Users\owesh\AppData\Local\Programs\Python\Python312\Lib\site-packages\django\db\utils.py", line 91, in __exit__
    raise dj_exc_value.with_traceback(traceback) from exc_value
  File "C:\Users\owesh\AppData\Local\Programs\Python\Python312\Lib\site-packages\django\db\backends\utils.py", line 89, in _execute
    return self.cursor.execute(sql, params)
           ^^^^^^^^^^^^^^^^^^^^^^^^^^^^^^^^
  File "C:\Users\owesh\AppData\Local\Programs\Python\Python312\Lib\site-packages\psycopg\cursor.py", line 97, in execute
    raise ex.with_traceback(None)
django.db.utils.IntegrityError: null value in column "phone" of relation "accounts_customuser" violates not-null constraint
DETAIL:  Failing row contains (2, pbkdf2_sha256$600000$bpGHxzoYeSe5q3eItOPHpr$8/apUtUML4v/fpECxWcW..., null, f, owesh, owesh, khan, oweshkhan96@gmail.com, t, t, 2025-09-01 23:55:44.350671-05, admin, null, null).
Internal Server Error: /register/
Traceback (most recent call last):
  File "C:\Users\owesh\AppData\Local\Programs\Python\Python312\Lib\site-packages\django\db\backends\utils.py", line 89, in _execute
    return self.cursor.execute(sql, params)
           ^^^^^^^^^^^^^^^^^^^^^^^^^^^^^^^^
  File "C:\Users\owesh\AppData\Local\Programs\Python\Python312\Lib\site-packages\psycopg\cursor.py", line 97, in execute
    raise ex.with_traceback(None)
psycopg.errors.NotNullViolation: null value in column "phone" of relation "accounts_customuser" violates not-null constraint
DETAIL:  Failing row contains (3, pbkdf2_sha256$600000$ckpfsMD2dC7tiISMdJYLmk$+pEVHnOc2BROPYUsvSzC..., null, f, owesh, owesh, khan, oweshkhan96@gmail.com, t, t, 2025-09-01 23:57:46.557991-05, admin, null, null).

The above exception was the direct cause of the following exception:

Traceback (most recent call last):
  File "C:\Users\owesh\AppData\Local\Programs\Python\Python312\Lib\site-packages\django\core\handlers\exception.py", line 55, in inner
    response = get_response(request)
               ^^^^^^^^^^^^^^^^^^^^^
  File "C:\Users\owesh\AppData\Local\Programs\Python\Python312\Lib\site-packages\django\core\handlers\base.py", line 197, in _get_response
    response = wrapped_callback(request, *callback_args, **callback_kwargs)
               ^^^^^^^^^^^^^^^^^^^^^^^^^^^^^^^^^^^^^^^^^^^^^^^^^^^^^^^^^^^^
  File "C:\Users\owesh\AppData\Local\Programs\Python\Python312\Lib\site-packages\django\utils\decorators.py", line 134, in _wrapper_view
    response = view_func(request, *args, **kwargs)
               ^^^^^^^^^^^^^^^^^^^^^^^^^^^^^^^^^^^
  File "D:\Dev\fuelmng\accounts\views.py", line 41, in login_register_view
    user = form.save()
           ^^^^^^^^^^^
  File "D:\Dev\fuelmng\accounts\forms.py", line 28, in save
    user.save()
  File "C:\Users\owesh\AppData\Local\Programs\Python\Python312\Lib\site-packages\django\contrib\auth\base_user.py", line 76, in save
    super().save(*args, **kwargs)
  File "C:\Users\owesh\AppData\Local\Programs\Python\Python312\Lib\site-packages\django\db\models\base.py", line 814, in save
    self.save_base(
  File "C:\Users\owesh\AppData\Local\Programs\Python\Python312\Lib\site-packages\django\db\models\base.py", line 877, in save_base
    updated = self._save_table(
              ^^^^^^^^^^^^^^^^^
  File "C:\Users\owesh\AppData\Local\Programs\Python\Python312\Lib\site-packages\django\db\models\base.py", line 1020, in _save_table
    results = self._do_insert(
              ^^^^^^^^^^^^^^^^
  File "C:\Users\owesh\AppData\Local\Programs\Python\Python312\Lib\site-packages\django\db\models\base.py", line 1061, in _do_insert
    return manager._insert(
           ^^^^^^^^^^^^^^^^
  File "C:\Users\owesh\AppData\Local\Programs\Python\Python312\Lib\site-packages\django\db\models\manager.py", line 87, in manager_method
    return getattr(self.get_queryset(), name)(*args, **kwargs)
           ^^^^^^^^^^^^^^^^^^^^^^^^^^^^^^^^^^^^^^^^^^^^^^^^^^^
  File "C:\Users\owesh\AppData\Local\Programs\Python\Python312\Lib\site-packages\django\db\models\query.py", line 1805, in _insert
    return query.get_compiler(using=using).execute_sql(returning_fields)
           ^^^^^^^^^^^^^^^^^^^^^^^^^^^^^^^^^^^^^^^^^^^^^^^^^^^^^^^^^^^^^
  File "C:\Users\owesh\AppData\Local\Programs\Python\Python312\Lib\site-packages\django\db\models\sql\compiler.py", line 1822, in execute_sql
    cursor.execute(sql, params)
  File "C:\Users\owesh\AppData\Local\Programs\Python\Python312\Lib\site-packages\django\db\backends\utils.py", line 102, in execute
    return super().execute(sql, params)
           ^^^^^^^^^^^^^^^^^^^^^^^^^^^^
  File "C:\Users\owesh\AppData\Local\Programs\Python\Python312\Lib\site-packages\django\db\backends\utils.py", line 67, in execute
    return self._execute_with_wrappers(
           ^^^^^^^^^^^^^^^^^^^^^^^^^^^^
  File "C:\Users\owesh\AppData\Local\Programs\Python\Python312\Lib\site-packages\django\db\backends\utils.py", line 80, in _execute_with_wrappers
    return executor(sql, params, many, context)
           ^^^^^^^^^^^^^^^^^^^^^^^^^^^^^^^^^^^^
  File "C:\Users\owesh\AppData\Local\Programs\Python\Python312\Lib\site-packages\django\db\backends\utils.py", line 84, in _execute
    with self.db.wrap_database_errors:
  File "C:\Users\owesh\AppData\Local\Programs\Python\Python312\Lib\site-packages\django\db\utils.py", line 91, in __exit__
    raise dj_exc_value.with_traceback(traceback) from exc_value
  File "C:\Users\owesh\AppData\Local\Programs\Python\Python312\Lib\site-packages\django\db\backends\utils.py", line 89, in _execute
    return self.cursor.execute(sql, params)
           ^^^^^^^^^^^^^^^^^^^^^^^^^^^^^^^^
  File "C:\Users\owesh\AppData\Local\Programs\Python\Python312\Lib\site-packages\psycopg\cursor.py", line 97, in execute
    raise ex.with_traceback(None)
django.db.utils.IntegrityError: null value in column "phone" of relation "accounts_customuser" violates not-null constraint
DETAIL:  Failing row contains (3, pbkdf2_sha256$600000$ckpfsMD2dC7tiISMdJYLmk$+pEVHnOc2BROPYUsvSzC..., null, f, owesh, owesh, khan, oweshkhan96@gmail.com, t, t, 2025-09-01 23:57:46.557991-05, admin, null, null).
D:\Dev\fuelmng\accounts\forms.py changed, reloading.
Watching for file changes with StatReloader
Watching for file changes with StatReloader
Internal Server Error: /register/
Traceback (most recent call last):
  File "C:\Users\owesh\AppData\Local\Programs\Python\Python312\Lib\site-packages\django\db\backends\utils.py", line 89, in _execute
    return self.cursor.execute(sql, params)
           ^^^^^^^^^^^^^^^^^^^^^^^^^^^^^^^^
  File "C:\Users\owesh\AppData\Local\Programs\Python\Python312\Lib\site-packages\psycopg\cursor.py", line 97, in execute
    raise ex.with_traceback(None)
psycopg.errors.UndefinedColumn: column accounts_company.updated_at does not exist
LINE 1: ...ompany"."email", "accounts_company"."created_at", "accounts_...
                                                             ^
HINT:  Perhaps you meant to reference the column "accounts_company.created_at".

The above exception was the direct cause of the following exception:

Traceback (most recent call last):
  File "C:\Users\owesh\AppData\Local\Programs\Python\Python312\Lib\site-packages\django\core\handlers\exception.py", line 55, in inner
    response = get_response(request)
               ^^^^^^^^^^^^^^^^^^^^^
  File "C:\Users\owesh\AppData\Local\Programs\Python\Python312\Lib\site-packages\django\core\handlers\base.py", line 197, in _get_response
    response = wrapped_callback(request, *callback_args, **callback_kwargs)
               ^^^^^^^^^^^^^^^^^^^^^^^^^^^^^^^^^^^^^^^^^^^^^^^^^^^^^^^^^^^^
  File "C:\Users\owesh\AppData\Local\Programs\Python\Python312\Lib\site-packages\django\utils\decorators.py", line 134, in _wrapper_view
    response = view_func(request, *args, **kwargs)
               ^^^^^^^^^^^^^^^^^^^^^^^^^^^^^^^^^^^
  File "D:\Dev\fuelmng\accounts\views.py", line 41, in login_register_view
    user = form.save()
           ^^^^^^^^^^^
  File "D:\Dev\fuelmng\accounts\forms.py", line 35, in save
    company, created = Company.objects.get_or_create(
                       ^^^^^^^^^^^^^^^^^^^^^^^^^^^^^^
  File "C:\Users\owesh\AppData\Local\Programs\Python\Python312\Lib\site-packages\django\db\models\manager.py", line 87, in manager_method
    return getattr(self.get_queryset(), name)(*args, **kwargs)
           ^^^^^^^^^^^^^^^^^^^^^^^^^^^^^^^^^^^^^^^^^^^^^^^^^^^
  File "C:\Users\owesh\AppData\Local\Programs\Python\Python312\Lib\site-packages\django\db\models\query.py", line 916, in get_or_create
    return self.get(**kwargs), False
           ^^^^^^^^^^^^^^^^^^
  File "C:\Users\owesh\AppData\Local\Programs\Python\Python312\Lib\site-packages\django\db\models\query.py", line 633, in get
    num = len(clone)
          ^^^^^^^^^^
  File "C:\Users\owesh\AppData\Local\Programs\Python\Python312\Lib\site-packages\django\db\models\query.py", line 380, in __len__
    self._fetch_all()
  File "C:\Users\owesh\AppData\Local\Programs\Python\Python312\Lib\site-packages\django\db\models\query.py", line 1881, in _fetch_all
    self._result_cache = list(self._iterable_class(self))
                         ^^^^^^^^^^^^^^^^^^^^^^^^^^^^^^^^
  File "C:\Users\owesh\AppData\Local\Programs\Python\Python312\Lib\site-packages\django\db\models\query.py", line 91, in __iter__
    results = compiler.execute_sql(
              ^^^^^^^^^^^^^^^^^^^^^
  File "C:\Users\owesh\AppData\Local\Programs\Python\Python312\Lib\site-packages\django\db\models\sql\compiler.py", line 1562, in execute_sql
    cursor.execute(sql, params)
  File "C:\Users\owesh\AppData\Local\Programs\Python\Python312\Lib\site-packages\django\db\backends\utils.py", line 102, in execute
    return super().execute(sql, params)
           ^^^^^^^^^^^^^^^^^^^^^^^^^^^^
  File "C:\Users\owesh\AppData\Local\Programs\Python\Python312\Lib\site-packages\django\db\backends\utils.py", line 67, in execute
    return self._execute_with_wrappers(
           ^^^^^^^^^^^^^^^^^^^^^^^^^^^^
  File "C:\Users\owesh\AppData\Local\Programs\Python\Python312\Lib\site-packages\django\db\backends\utils.py", line 80, in _execute_with_wrappers
    return executor(sql, params, many, context)
           ^^^^^^^^^^^^^^^^^^^^^^^^^^^^^^^^^^^^
  File "C:\Users\owesh\AppData\Local\Programs\Python\Python312\Lib\site-packages\django\db\backends\utils.py", line 84, in _execute
    with self.db.wrap_database_errors:
  File "C:\Users\owesh\AppData\Local\Programs\Python\Python312\Lib\site-packages\django\db\utils.py", line 91, in __exit__
    raise dj_exc_value.with_traceback(traceback) from exc_value
  File "C:\Users\owesh\AppData\Local\Programs\Python\Python312\Lib\site-packages\django\db\backends\utils.py", line 89, in _execute
    return self.cursor.execute(sql, params)
           ^^^^^^^^^^^^^^^^^^^^^^^^^^^^^^^^
  File "C:\Users\owesh\AppData\Local\Programs\Python\Python312\Lib\site-packages\psycopg\cursor.py", line 97, in execute
    raise ex.with_traceback(None)
django.db.utils.ProgrammingError: column accounts_company.updated_at does not exist
LINE 1: ...ompany"."email", "accounts_company"."created_at", "accounts_...
                                                             ^
HINT:  Perhaps you meant to reference the column "accounts_company.created_at".
Internal Server Error: /admin/accounts/customuser/
Traceback (most recent call last):
  File "C:\Users\owesh\AppData\Local\Programs\Python\Python312\Lib\site-packages\django\db\backends\utils.py", line 89, in _execute
    return self.cursor.execute(sql, params)
           ^^^^^^^^^^^^^^^^^^^^^^^^^^^^^^^^
  File "C:\Users\owesh\AppData\Local\Programs\Python\Python312\Lib\site-packages\psycopg\cursor.py", line 97, in execute
    raise ex.with_traceback(None)
psycopg.errors.UndefinedColumn: column accounts_company.updated_at does not exist
LINE 1: ...ompany"."email", "accounts_company"."created_at", "accounts_...
                                                             ^
HINT:  Perhaps you meant to reference the column "accounts_company.created_at".

The above exception was the direct cause of the following exception:

Traceback (most recent call last):
  File "C:\Users\owesh\AppData\Local\Programs\Python\Python312\Lib\site-packages\django\core\handlers\exception.py", line 55, in inner
    response = get_response(request)
               ^^^^^^^^^^^^^^^^^^^^^
  File "C:\Users\owesh\AppData\Local\Programs\Python\Python312\Lib\site-packages\django\core\handlers\base.py", line 197, in _get_response
    response = wrapped_callback(request, *callback_args, **callback_kwargs)
               ^^^^^^^^^^^^^^^^^^^^^^^^^^^^^^^^^^^^^^^^^^^^^^^^^^^^^^^^^^^^
  File "C:\Users\owesh\AppData\Local\Programs\Python\Python312\Lib\site-packages\django\contrib\admin\options.py", line 688, in wrapper
    return self.admin_site.admin_view(view)(*args, **kwargs)
           ^^^^^^^^^^^^^^^^^^^^^^^^^^^^^^^^^^^^^^^^^^^^^^^^^
  File "C:\Users\owesh\AppData\Local\Programs\Python\Python312\Lib\site-packages\django\utils\decorators.py", line 134, in _wrapper_view
    response = view_func(request, *args, **kwargs)
               ^^^^^^^^^^^^^^^^^^^^^^^^^^^^^^^^^^^
  File "C:\Users\owesh\AppData\Local\Programs\Python\Python312\Lib\site-packages\django\views\decorators\cache.py", line 62, in _wrapper_view_func
    response = view_func(request, *args, **kwargs)
               ^^^^^^^^^^^^^^^^^^^^^^^^^^^^^^^^^^^
  File "C:\Users\owesh\AppData\Local\Programs\Python\Python312\Lib\site-packages\django\contrib\admin\sites.py", line 242, in inner
    return view(request, *args, **kwargs)
           ^^^^^^^^^^^^^^^^^^^^^^^^^^^^^^
  File "C:\Users\owesh\AppData\Local\Programs\Python\Python312\Lib\site-packages\django\utils\decorators.py", line 46, in _wrapper
    return bound_method(*args, **kwargs)
           ^^^^^^^^^^^^^^^^^^^^^^^^^^^^^
  File "C:\Users\owesh\AppData\Local\Programs\Python\Python312\Lib\site-packages\django\utils\decorators.py", line 134, in _wrapper_view
    response = view_func(request, *args, **kwargs)
               ^^^^^^^^^^^^^^^^^^^^^^^^^^^^^^^^^^^
  File "C:\Users\owesh\AppData\Local\Programs\Python\Python312\Lib\site-packages\django\contrib\admin\options.py", line 1926, in changelist_view
    cl = self.get_changelist_instance(request)
         ^^^^^^^^^^^^^^^^^^^^^^^^^^^^^^^^^^^^^
  File "C:\Users\owesh\AppData\Local\Programs\Python\Python312\Lib\site-packages\django\contrib\admin\options.py", line 836, in get_changelist_instance
    return ChangeList(
           ^^^^^^^^^^^
  File "C:\Users\owesh\AppData\Local\Programs\Python\Python312\Lib\site-packages\django\contrib\admin\views\main.py", line 122, in __init__
    self.queryset = self.get_queryset(request)
                    ^^^^^^^^^^^^^^^^^^^^^^^^^^
  File "C:\Users\owesh\AppData\Local\Programs\Python\Python312\Lib\site-packages\django\contrib\admin\views\main.py", line 503, in get_queryset
    ) = self.get_filters(request)
        ^^^^^^^^^^^^^^^^^^^^^^^^^
  File "C:\Users\owesh\AppData\Local\Programs\Python\Python312\Lib\site-packages\django\contrib\admin\views\main.py", line 182, in get_filters
    spec = field_list_filter_class(
           ^^^^^^^^^^^^^^^^^^^^^^^^
  File "C:\Users\owesh\AppData\Local\Programs\Python\Python312\Lib\site-packages\django\contrib\admin\filters.py", line 175, in create
    return list_filter_class(
           ^^^^^^^^^^^^^^^^^^
  File "C:\Users\owesh\AppData\Local\Programs\Python\Python312\Lib\site-packages\django\contrib\admin\filters.py", line 188, in __init__
    self.lookup_choices = self.field_choices(field, request, model_admin)
                          ^^^^^^^^^^^^^^^^^^^^^^^^^^^^^^^^^^^^^^^^^^^^^^^
  File "C:\Users\owesh\AppData\Local\Programs\Python\Python312\Lib\site-packages\django\contrib\admin\filters.py", line 225, in field_choices
    return field.get_choices(include_blank=False, ordering=ordering)
           ^^^^^^^^^^^^^^^^^^^^^^^^^^^^^^^^^^^^^^^^^^^^^^^^^^^^^^^^^
  File "C:\Users\owesh\AppData\Local\Programs\Python\Python312\Lib\site-packages\django\db\models\fields\__init__.py", line 1009, in get_choices
    return (blank_choice if include_blank else []) + [
                                                     ^
  File "C:\Users\owesh\AppData\Local\Programs\Python\Python312\Lib\site-packages\django\db\models\query.py", line 398, in __iter__
    self._fetch_all()
  File "C:\Users\owesh\AppData\Local\Programs\Python\Python312\Lib\site-packages\django\db\models\query.py", line 1881, in _fetch_all
    self._result_cache = list(self._iterable_class(self))
                         ^^^^^^^^^^^^^^^^^^^^^^^^^^^^^^^^
  File "C:\Users\owesh\AppData\Local\Programs\Python\Python312\Lib\site-packages\django\db\models\query.py", line 91, in __iter__
    results = compiler.execute_sql(
              ^^^^^^^^^^^^^^^^^^^^^
  File "C:\Users\owesh\AppData\Local\Programs\Python\Python312\Lib\site-packages\django\db\models\sql\compiler.py", line 1562, in execute_sql
    cursor.execute(sql, params)
  File "C:\Users\owesh\AppData\Local\Programs\Python\Python312\Lib\site-packages\django\db\backends\utils.py", line 102, in execute
    return super().execute(sql, params)
           ^^^^^^^^^^^^^^^^^^^^^^^^^^^^
  File "C:\Users\owesh\AppData\Local\Programs\Python\Python312\Lib\site-packages\django\db\backends\utils.py", line 67, in execute
    return self._execute_with_wrappers(
           ^^^^^^^^^^^^^^^^^^^^^^^^^^^^
  File "C:\Users\owesh\AppData\Local\Programs\Python\Python312\Lib\site-packages\django\db\backends\utils.py", line 80, in _execute_with_wrappers
    return executor(sql, params, many, context)
           ^^^^^^^^^^^^^^^^^^^^^^^^^^^^^^^^^^^^
  File "C:\Users\owesh\AppData\Local\Programs\Python\Python312\Lib\site-packages\django\db\backends\utils.py", line 84, in _execute
    with self.db.wrap_database_errors:
  File "C:\Users\owesh\AppData\Local\Programs\Python\Python312\Lib\site-packages\django\db\utils.py", line 91, in __exit__
    raise dj_exc_value.with_traceback(traceback) from exc_value
  File "C:\Users\owesh\AppData\Local\Programs\Python\Python312\Lib\site-packages\django\db\backends\utils.py", line 89, in _execute
    return self.cursor.execute(sql, params)
           ^^^^^^^^^^^^^^^^^^^^^^^^^^^^^^^^
  File "C:\Users\owesh\AppData\Local\Programs\Python\Python312\Lib\site-packages\psycopg\cursor.py", line 97, in execute
    raise ex.with_traceback(None)
django.db.utils.ProgrammingError: column accounts_company.updated_at does not exist
LINE 1: ...ompany"."email", "accounts_company"."created_at", "accounts_...
                                                             ^
HINT:  Perhaps you meant to reference the column "accounts_company.created_at".
Forbidden (CSRF token from POST incorrect.): /register/
Internal Server Error: /register/
Traceback (most recent call last):
  File "C:\Users\owesh\AppData\Local\Programs\Python\Python312\Lib\site-packages\django\db\backends\utils.py", line 89, in _execute
    return self.cursor.execute(sql, params)
           ^^^^^^^^^^^^^^^^^^^^^^^^^^^^^^^^
  File "C:\Users\owesh\AppData\Local\Programs\Python\Python312\Lib\site-packages\psycopg\cursor.py", line 97, in execute
    raise ex.with_traceback(None)
psycopg.errors.UndefinedColumn: column accounts_company.updated_at does not exist
LINE 1: ...ompany"."email", "accounts_company"."created_at", "accounts_...
                                                             ^
HINT:  Perhaps you meant to reference the column "accounts_company.created_at".

The above exception was the direct cause of the following exception:

Traceback (most recent call last):
  File "C:\Users\owesh\AppData\Local\Programs\Python\Python312\Lib\site-packages\django\core\handlers\exception.py", line 55, in inner
    response = get_response(request)
               ^^^^^^^^^^^^^^^^^^^^^
  File "C:\Users\owesh\AppData\Local\Programs\Python\Python312\Lib\site-packages\django\core\handlers\base.py", line 197, in _get_response
    response = wrapped_callback(request, *callback_args, **callback_kwargs)
               ^^^^^^^^^^^^^^^^^^^^^^^^^^^^^^^^^^^^^^^^^^^^^^^^^^^^^^^^^^^^
  File "C:\Users\owesh\AppData\Local\Programs\Python\Python312\Lib\site-packages\django\utils\decorators.py", line 134, in _wrapper_view
    response = view_func(request, *args, **kwargs)
               ^^^^^^^^^^^^^^^^^^^^^^^^^^^^^^^^^^^
  File "D:\Dev\fuelmng\accounts\views.py", line 41, in login_register_view
    user = form.save()
           ^^^^^^^^^^^
  File "D:\Dev\fuelmng\accounts\forms.py", line 35, in save
    company, created = Company.objects.get_or_create(
                       ^^^^^^^^^^^^^^^^^^^^^^^^^^^^^^
  File "C:\Users\owesh\AppData\Local\Programs\Python\Python312\Lib\site-packages\django\db\models\manager.py", line 87, in manager_method
    return getattr(self.get_queryset(), name)(*args, **kwargs)
           ^^^^^^^^^^^^^^^^^^^^^^^^^^^^^^^^^^^^^^^^^^^^^^^^^^^
  File "C:\Users\owesh\AppData\Local\Programs\Python\Python312\Lib\site-packages\django\db\models\query.py", line 916, in get_or_create
    return self.get(**kwargs), False
           ^^^^^^^^^^^^^^^^^^
  File "C:\Users\owesh\AppData\Local\Programs\Python\Python312\Lib\site-packages\django\db\models\query.py", line 633, in get
    num = len(clone)
          ^^^^^^^^^^
  File "C:\Users\owesh\AppData\Local\Programs\Python\Python312\Lib\site-packages\django\db\models\query.py", line 380, in __len__
    self._fetch_all()
  File "C:\Users\owesh\AppData\Local\Programs\Python\Python312\Lib\site-packages\django\db\models\query.py", line 1881, in _fetch_all
    self._result_cache = list(self._iterable_class(self))
                         ^^^^^^^^^^^^^^^^^^^^^^^^^^^^^^^^
  File "C:\Users\owesh\AppData\Local\Programs\Python\Python312\Lib\site-packages\django\db\models\query.py", line 91, in __iter__
    results = compiler.execute_sql(
              ^^^^^^^^^^^^^^^^^^^^^
  File "C:\Users\owesh\AppData\Local\Programs\Python\Python312\Lib\site-packages\django\db\models\sql\compiler.py", line 1562, in execute_sql
    cursor.execute(sql, params)
  File "C:\Users\owesh\AppData\Local\Programs\Python\Python312\Lib\site-packages\django\db\backends\utils.py", line 102, in execute
    return super().execute(sql, params)
           ^^^^^^^^^^^^^^^^^^^^^^^^^^^^
  File "C:\Users\owesh\AppData\Local\Programs\Python\Python312\Lib\site-packages\django\db\backends\utils.py", line 67, in execute
    return self._execute_with_wrappers(
           ^^^^^^^^^^^^^^^^^^^^^^^^^^^^
  File "C:\Users\owesh\AppData\Local\Programs\Python\Python312\Lib\site-packages\django\db\backends\utils.py", line 80, in _execute_with_wrappers
    return executor(sql, params, many, context)
           ^^^^^^^^^^^^^^^^^^^^^^^^^^^^^^^^^^^^
  File "C:\Users\owesh\AppData\Local\Programs\Python\Python312\Lib\site-packages\django\db\backends\utils.py", line 84, in _execute
    with self.db.wrap_database_errors:
  File "C:\Users\owesh\AppData\Local\Programs\Python\Python312\Lib\site-packages\django\db\utils.py", line 91, in __exit__
    raise dj_exc_value.with_traceback(traceback) from exc_value
  File "C:\Users\owesh\AppData\Local\Programs\Python\Python312\Lib\site-packages\django\db\backends\utils.py", line 89, in _execute
    return self.cursor.execute(sql, params)
           ^^^^^^^^^^^^^^^^^^^^^^^^^^^^^^^^
  File "C:\Users\owesh\AppData\Local\Programs\Python\Python312\Lib\site-packages\psycopg\cursor.py", line 97, in execute
    raise ex.with_traceback(None)
django.db.utils.ProgrammingError: column accounts_company.updated_at does not exist
LINE 1: ...ompany"."email", "accounts_company"."created_at", "accounts_...
                                                             ^
HINT:  Perhaps you meant to reference the column "accounts_company.created_at".
D:\Dev\fuelmng\accounts\models.py changed, reloading.
Watching for file changes with StatReloader
Watching for file changes with StatReloader
Internal Server Error: /register/
Traceback (most recent call last):
  File "C:\Users\owesh\AppData\Local\Programs\Python\Python312\Lib\site-packages\django\db\backends\utils.py", line 89, in _execute
    return self.cursor.execute(sql, params)
           ^^^^^^^^^^^^^^^^^^^^^^^^^^^^^^^^
  File "C:\Users\owesh\AppData\Local\Programs\Python\Python312\Lib\site-packages\psycopg\cursor.py", line 97, in execute
    raise ex.with_traceback(None)
psycopg.errors.UndefinedColumn: column accounts_company.updated_at does not exist
LINE 1: ...ompany"."email", "accounts_company"."created_at", "accounts_...
                                                             ^
HINT:  Perhaps you meant to reference the column "accounts_company.created_at".

The above exception was the direct cause of the following exception:

Traceback (most recent call last):
  File "C:\Users\owesh\AppData\Local\Programs\Python\Python312\Lib\site-packages\django\core\handlers\exception.py", line 55, in inner
    response = get_response(request)
               ^^^^^^^^^^^^^^^^^^^^^
  File "C:\Users\owesh\AppData\Local\Programs\Python\Python312\Lib\site-packages\django\core\handlers\base.py", line 197, in _get_response
    response = wrapped_callback(request, *callback_args, **callback_kwargs)
               ^^^^^^^^^^^^^^^^^^^^^^^^^^^^^^^^^^^^^^^^^^^^^^^^^^^^^^^^^^^^
  File "C:\Users\owesh\AppData\Local\Programs\Python\Python312\Lib\site-packages\django\utils\decorators.py", line 134, in _wrapper_view
    response = view_func(request, *args, **kwargs)
               ^^^^^^^^^^^^^^^^^^^^^^^^^^^^^^^^^^^
  File "D:\Dev\fuelmng\accounts\views.py", line 41, in login_register_view
    user = form.save()
           ^^^^^^^^^^^
  File "D:\Dev\fuelmng\accounts\forms.py", line 35, in save
    company, created = Company.objects.get_or_create(
                       ^^^^^^^^^^^^^^^^^^^^^^^^^^^^^^
  File "C:\Users\owesh\AppData\Local\Programs\Python\Python312\Lib\site-packages\django\db\models\manager.py", line 87, in manager_method
    return getattr(self.get_queryset(), name)(*args, **kwargs)
           ^^^^^^^^^^^^^^^^^^^^^^^^^^^^^^^^^^^^^^^^^^^^^^^^^^^
  File "C:\Users\owesh\AppData\Local\Programs\Python\Python312\Lib\site-packages\django\db\models\query.py", line 916, in get_or_create
    return self.get(**kwargs), False
           ^^^^^^^^^^^^^^^^^^
  File "C:\Users\owesh\AppData\Local\Programs\Python\Python312\Lib\site-packages\django\db\models\query.py", line 633, in get
    num = len(clone)
          ^^^^^^^^^^
  File "C:\Users\owesh\AppData\Local\Programs\Python\Python312\Lib\site-packages\django\db\models\query.py", line 380, in __len__
    self._fetch_all()
  File "C:\Users\owesh\AppData\Local\Programs\Python\Python312\Lib\site-packages\django\db\models\query.py", line 1881, in _fetch_all
    self._result_cache = list(self._iterable_class(self))
                         ^^^^^^^^^^^^^^^^^^^^^^^^^^^^^^^^
  File "C:\Users\owesh\AppData\Local\Programs\Python\Python312\Lib\site-packages\django\db\models\query.py", line 91, in __iter__
    results = compiler.execute_sql(
              ^^^^^^^^^^^^^^^^^^^^^
  File "C:\Users\owesh\AppData\Local\Programs\Python\Python312\Lib\site-packages\django\db\models\sql\compiler.py", line 1562, in execute_sql
    cursor.execute(sql, params)
  File "C:\Users\owesh\AppData\Local\Programs\Python\Python312\Lib\site-packages\django\db\backends\utils.py", line 102, in execute
    return super().execute(sql, params)
           ^^^^^^^^^^^^^^^^^^^^^^^^^^^^
  File "C:\Users\owesh\AppData\Local\Programs\Python\Python312\Lib\site-packages\django\db\backends\utils.py", line 67, in execute
    return self._execute_with_wrappers(
           ^^^^^^^^^^^^^^^^^^^^^^^^^^^^
  File "C:\Users\owesh\AppData\Local\Programs\Python\Python312\Lib\site-packages\django\db\backends\utils.py", line 80, in _execute_with_wrappers
    return executor(sql, params, many, context)
           ^^^^^^^^^^^^^^^^^^^^^^^^^^^^^^^^^^^^
  File "C:\Users\owesh\AppData\Local\Programs\Python\Python312\Lib\site-packages\django\db\backends\utils.py", line 84, in _execute
    with self.db.wrap_database_errors:
  File "C:\Users\owesh\AppData\Local\Programs\Python\Python312\Lib\site-packages\django\db\utils.py", line 91, in __exit__
    raise dj_exc_value.with_traceback(traceback) from exc_value
  File "C:\Users\owesh\AppData\Local\Programs\Python\Python312\Lib\site-packages\django\db\backends\utils.py", line 89, in _execute
    return self.cursor.execute(sql, params)
           ^^^^^^^^^^^^^^^^^^^^^^^^^^^^^^^^
  File "C:\Users\owesh\AppData\Local\Programs\Python\Python312\Lib\site-packages\psycopg\cursor.py", line 97, in execute
    raise ex.with_traceback(None)
django.db.utils.ProgrammingError: column accounts_company.updated_at does not exist
LINE 1: ...ompany"."email", "accounts_company"."created_at", "accounts_...
                                                             ^
HINT:  Perhaps you meant to reference the column "accounts_company.created_at".
Watching for file changes with StatReloader
Internal Server Error: /register/
Traceback (most recent call last):
  File "C:\Users\owesh\AppData\Local\Programs\Python\Python312\Lib\site-packages\django\db\models\query.py", line 916, in get_or_create
    return self.get(**kwargs), False
           ^^^^^^^^^^^^^^^^^^
  File "C:\Users\owesh\AppData\Local\Programs\Python\Python312\Lib\site-packages\django\db\models\query.py", line 637, in get
    raise self.model.DoesNotExist(
accounts.models.Company.DoesNotExist: Company matching query does not exist.

During handling of the above exception, another exception occurred:

Traceback (most recent call last):
  File "C:\Users\owesh\AppData\Local\Programs\Python\Python312\Lib\site-packages\django\db\backends\utils.py", line 89, in _execute
    return self.cursor.execute(sql, params)
           ^^^^^^^^^^^^^^^^^^^^^^^^^^^^^^^^
  File "C:\Users\owesh\AppData\Local\Programs\Python\Python312\Lib\site-packages\psycopg\cursor.py", line 97, in execute
    raise ex.with_traceback(None)
psycopg.errors.NotNullViolation: null value in column "address" of relation "accounts_company" violates not-null constraint
DETAIL:  Failing row contains (2, Develup tech, null, null, null, null, 2025-09-02 00:37:19.669441-05, 2025-09-02 00:37:19.669441-05).

The above exception was the direct cause of the following exception:

Traceback (most recent call last):
  File "C:\Users\owesh\AppData\Local\Programs\Python\Python312\Lib\site-packages\django\core\handlers\exception.py", line 55, in inner
    response = get_response(request)
               ^^^^^^^^^^^^^^^^^^^^^
  File "C:\Users\owesh\AppData\Local\Programs\Python\Python312\Lib\site-packages\django\core\handlers\base.py", line 197, in _get_response
    response = wrapped_callback(request, *callback_args, **callback_kwargs)
               ^^^^^^^^^^^^^^^^^^^^^^^^^^^^^^^^^^^^^^^^^^^^^^^^^^^^^^^^^^^^
  File "C:\Users\owesh\AppData\Local\Programs\Python\Python312\Lib\site-packages\django\utils\decorators.py", line 134, in _wrapper_view
    response = view_func(request, *args, **kwargs)
               ^^^^^^^^^^^^^^^^^^^^^^^^^^^^^^^^^^^
  File "D:\Dev\fuelmng\accounts\views.py", line 41, in login_register_view
    user = form.save()
           ^^^^^^^^^^^
  File "D:\Dev\fuelmng\accounts\forms.py", line 35, in save
    company, created = Company.objects.get_or_create(
                       ^^^^^^^^^^^^^^^^^^^^^^^^^^^^^^
  File "C:\Users\owesh\AppData\Local\Programs\Python\Python312\Lib\site-packages\django\db\models\manager.py", line 87, in manager_method
    return getattr(self.get_queryset(), name)(*args, **kwargs)
           ^^^^^^^^^^^^^^^^^^^^^^^^^^^^^^^^^^^^^^^^^^^^^^^^^^^
  File "C:\Users\owesh\AppData\Local\Programs\Python\Python312\Lib\site-packages\django\db\models\query.py", line 923, in get_or_create
    return self.create(**params), True
           ^^^^^^^^^^^^^^^^^^^^^
  File "C:\Users\owesh\AppData\Local\Programs\Python\Python312\Lib\site-packages\django\db\models\query.py", line 658, in create
    obj.save(force_insert=True, using=self.db)
  File "C:\Users\owesh\AppData\Local\Programs\Python\Python312\Lib\site-packages\django\db\models\base.py", line 814, in save
    self.save_base(
  File "C:\Users\owesh\AppData\Local\Programs\Python\Python312\Lib\site-packages\django\db\models\base.py", line 877, in save_base
    updated = self._save_table(
              ^^^^^^^^^^^^^^^^^
  File "C:\Users\owesh\AppData\Local\Programs\Python\Python312\Lib\site-packages\django\db\models\base.py", line 1020, in _save_table
    results = self._do_insert(
              ^^^^^^^^^^^^^^^^
  File "C:\Users\owesh\AppData\Local\Programs\Python\Python312\Lib\site-packages\django\db\models\base.py", line 1061, in _do_insert
    return manager._insert(
           ^^^^^^^^^^^^^^^^
  File "C:\Users\owesh\AppData\Local\Programs\Python\Python312\Lib\site-packages\django\db\models\manager.py", line 87, in manager_method
    return getattr(self.get_queryset(), name)(*args, **kwargs)
           ^^^^^^^^^^^^^^^^^^^^^^^^^^^^^^^^^^^^^^^^^^^^^^^^^^^
  File "C:\Users\owesh\AppData\Local\Programs\Python\Python312\Lib\site-packages\django\db\models\query.py", line 1805, in _insert
    return query.get_compiler(using=using).execute_sql(returning_fields)
           ^^^^^^^^^^^^^^^^^^^^^^^^^^^^^^^^^^^^^^^^^^^^^^^^^^^^^^^^^^^^^
  File "C:\Users\owesh\AppData\Local\Programs\Python\Python312\Lib\site-packages\django\db\models\sql\compiler.py", line 1822, in execute_sql
    cursor.execute(sql, params)
  File "C:\Users\owesh\AppData\Local\Programs\Python\Python312\Lib\site-packages\django\db\backends\utils.py", line 102, in execute
    return super().execute(sql, params)
           ^^^^^^^^^^^^^^^^^^^^^^^^^^^^
  File "C:\Users\owesh\AppData\Local\Programs\Python\Python312\Lib\site-packages\django\db\backends\utils.py", line 67, in execute
    return self._execute_with_wrappers(
           ^^^^^^^^^^^^^^^^^^^^^^^^^^^^
  File "C:\Users\owesh\AppData\Local\Programs\Python\Python312\Lib\site-packages\django\db\backends\utils.py", line 80, in _execute_with_wrappers
    return executor(sql, params, many, context)
           ^^^^^^^^^^^^^^^^^^^^^^^^^^^^^^^^^^^^
  File "C:\Users\owesh\AppData\Local\Programs\Python\Python312\Lib\site-packages\django\db\backends\utils.py", line 84, in _execute
    with self.db.wrap_database_errors:
  File "C:\Users\owesh\AppData\Local\Programs\Python\Python312\Lib\site-packages\django\db\utils.py", line 91, in __exit__
    raise dj_exc_value.with_traceback(traceback) from exc_value
  File "C:\Users\owesh\AppData\Local\Programs\Python\Python312\Lib\site-packages\django\db\backends\utils.py", line 89, in _execute
    return self.cursor.execute(sql, params)
           ^^^^^^^^^^^^^^^^^^^^^^^^^^^^^^^^
  File "C:\Users\owesh\AppData\Local\Programs\Python\Python312\Lib\site-packages\psycopg\cursor.py", line 97, in execute
    raise ex.with_traceback(None)
django.db.utils.IntegrityError: null value in column "address" of relation "accounts_company" violates not-null constraint
DETAIL:  Failing row contains (2, Develup tech, null, null, null, null, 2025-09-02 00:37:19.669441-05, 2025-09-02 00:37:19.669441-05).
D:\Dev\fuelmng\accounts\models.py changed, reloading.
Watching for file changes with StatReloader
Watching for file changes with StatReloader
Not Found: /dashboard/analytics-data/
Watching for file changes with StatReloader
Not Found: /dashboard/analytics-data/
Not Found: /receipts/
Not Found: /receipts/
Not Found: /dashboard/analytics-data/
Not Found: /receipts/
D:\Dev\fuelmng\fuel_management\urls.py changed, reloading.
Watching for file changes with StatReloader
Watching for file changes with StatReloader
D:\Dev\fuelmng\drivers\views.py changed, reloading.
Watching for file changes with StatReloader
D:\Dev\fuelmng\drivers\forms.py changed, reloading.
Watching for file changes with StatReloader
Watching for file changes with StatReloader
D:\Dev\fuelmng\drivers\views.py changed, reloading.
Watching for file changes with StatReloader
D:\Dev\fuelmng\drivers\forms.py changed, reloading.
Watching for file changes with StatReloader
Watching for file changes with StatReloader
Internal Server Error: /dashboard/drivers/create/
Traceback (most recent call last):
  File "C:\Users\owesh\AppData\Local\Programs\Python\Python312\Lib\site-packages\django\db\backends\utils.py", line 89, in _execute
    return self.cursor.execute(sql, params)
           ^^^^^^^^^^^^^^^^^^^^^^^^^^^^^^^^
  File "C:\Users\owesh\AppData\Local\Programs\Python\Python312\Lib\site-packages\psycopg\cursor.py", line 97, in execute
    raise ex.with_traceback(None)
psycopg.errors.UndefinedColumn: column accounts_customuser.is_email_verified does not exist
LINE 1: ...ser"."company_id", "accounts_customuser"."phone", "accounts_...
                                                             ^

The above exception was the direct cause of the following exception:

Traceback (most recent call last):
  File "C:\Users\owesh\AppData\Local\Programs\Python\Python312\Lib\site-packages\django\core\handlers\exception.py", line 55, in inner
    response = get_response(request)
               ^^^^^^^^^^^^^^^^^^^^^
  File "C:\Users\owesh\AppData\Local\Programs\Python\Python312\Lib\site-packages\django\core\handlers\base.py", line 197, in _get_response
    response = wrapped_callback(request, *callback_args, **callback_kwargs)
               ^^^^^^^^^^^^^^^^^^^^^^^^^^^^^^^^^^^^^^^^^^^^^^^^^^^^^^^^^^^^
  File "C:\Users\owesh\AppData\Local\Programs\Python\Python312\Lib\site-packages\django\contrib\auth\decorators.py", line 22, in _wrapper_view
    if test_func(request.user):
       ^^^^^^^^^^^^^^^^^^^^^^^
  File "C:\Users\owesh\AppData\Local\Programs\Python\Python312\Lib\site-packages\django\contrib\auth\decorators.py", line 51, in <lambda>
    lambda u: u.is_authenticated,
              ^^^^^^^^^^^^^^^^^^
  File "C:\Users\owesh\AppData\Local\Programs\Python\Python312\Lib\site-packages\django\utils\functional.py", line 266, in inner
    self._setup()
  File "C:\Users\owesh\AppData\Local\Programs\Python\Python312\Lib\site-packages\django\utils\functional.py", line 419, in _setup
    self._wrapped = self._setupfunc()
                    ^^^^^^^^^^^^^^^^^
  File "C:\Users\owesh\AppData\Local\Programs\Python\Python312\Lib\site-packages\django\contrib\auth\middleware.py", line 25, in <lambda>
    request.user = SimpleLazyObject(lambda: get_user(request))
                                            ^^^^^^^^^^^^^^^^^
  File "C:\Users\owesh\AppData\Local\Programs\Python\Python312\Lib\site-packages\django\contrib\auth\middleware.py", line 11, in get_user
    request._cached_user = auth.get_user(request)
                           ^^^^^^^^^^^^^^^^^^^^^^
  File "C:\Users\owesh\AppData\Local\Programs\Python\Python312\Lib\site-packages\django\contrib\auth\__init__.py", line 198, in get_user
    user = backend.get_user(user_id)
           ^^^^^^^^^^^^^^^^^^^^^^^^^
  File "C:\Users\owesh\AppData\Local\Programs\Python\Python312\Lib\site-packages\django\contrib\auth\backends.py", line 161, in get_user
    user = UserModel._default_manager.get(pk=user_id)
           ^^^^^^^^^^^^^^^^^^^^^^^^^^^^^^^^^^^^^^^^^^
  File "C:\Users\owesh\AppData\Local\Programs\Python\Python312\Lib\site-packages\django\db\models\manager.py", line 87, in manager_method
    return getattr(self.get_queryset(), name)(*args, **kwargs)
           ^^^^^^^^^^^^^^^^^^^^^^^^^^^^^^^^^^^^^^^^^^^^^^^^^^^
  File "C:\Users\owesh\AppData\Local\Programs\Python\Python312\Lib\site-packages\django\db\models\query.py", line 633, in get
    num = len(clone)
          ^^^^^^^^^^
  File "C:\Users\owesh\AppData\Local\Programs\Python\Python312\Lib\site-packages\django\db\models\query.py", line 380, in __len__
    self._fetch_all()
  File "C:\Users\owesh\AppData\Local\Programs\Python\Python312\Lib\site-packages\django\db\models\query.py", line 1881, in _fetch_all
    self._result_cache = list(self._iterable_class(self))
                         ^^^^^^^^^^^^^^^^^^^^^^^^^^^^^^^^
  File "C:\Users\owesh\AppData\Local\Programs\Python\Python312\Lib\site-packages\django\db\models\query.py", line 91, in __iter__
    results = compiler.execute_sql(
              ^^^^^^^^^^^^^^^^^^^^^
  File "C:\Users\owesh\AppData\Local\Programs\Python\Python312\Lib\site-packages\django\db\models\sql\compiler.py", line 1562, in execute_sql
    cursor.execute(sql, params)
  File "C:\Users\owesh\AppData\Local\Programs\Python\Python312\Lib\site-packages\django\db\backends\utils.py", line 102, in execute
    return super().execute(sql, params)
           ^^^^^^^^^^^^^^^^^^^^^^^^^^^^
  File "C:\Users\owesh\AppData\Local\Programs\Python\Python312\Lib\site-packages\django\db\backends\utils.py", line 67, in execute
    return self._execute_with_wrappers(
           ^^^^^^^^^^^^^^^^^^^^^^^^^^^^
  File "C:\Users\owesh\AppData\Local\Programs\Python\Python312\Lib\site-packages\django\db\backends\utils.py", line 80, in _execute_with_wrappers
    return executor(sql, params, many, context)
           ^^^^^^^^^^^^^^^^^^^^^^^^^^^^^^^^^^^^
  File "C:\Users\owesh\AppData\Local\Programs\Python\Python312\Lib\site-packages\django\db\backends\utils.py", line 84, in _execute
    with self.db.wrap_database_errors:
  File "C:\Users\owesh\AppData\Local\Programs\Python\Python312\Lib\site-packages\django\db\utils.py", line 91, in __exit__
    raise dj_exc_value.with_traceback(traceback) from exc_value
  File "C:\Users\owesh\AppData\Local\Programs\Python\Python312\Lib\site-packages\django\db\backends\utils.py", line 89, in _execute
    return self.cursor.execute(sql, params)
           ^^^^^^^^^^^^^^^^^^^^^^^^^^^^^^^^
  File "C:\Users\owesh\AppData\Local\Programs\Python\Python312\Lib\site-packages\psycopg\cursor.py", line 97, in execute
    raise ex.with_traceback(None)
django.db.utils.ProgrammingError: column accounts_customuser.is_email_verified does not exist
LINE 1: ...ser"."company_id", "accounts_customuser"."phone", "accounts_...
                                                             ^
Internal Server Error: /dashboard/drivers/
Traceback (most recent call last):
  File "C:\Users\owesh\AppData\Local\Programs\Python\Python312\Lib\site-packages\django\db\backends\utils.py", line 89, in _execute
    return self.cursor.execute(sql, params)
           ^^^^^^^^^^^^^^^^^^^^^^^^^^^^^^^^
  File "C:\Users\owesh\AppData\Local\Programs\Python\Python312\Lib\site-packages\psycopg\cursor.py", line 97, in execute
    raise ex.with_traceback(None)
psycopg.errors.UndefinedColumn: column accounts_customuser.is_email_verified does not exist
LINE 1: ...ser"."company_id", "accounts_customuser"."phone", "accounts_...
                                                             ^

The above exception was the direct cause of the following exception:

Traceback (most recent call last):
  File "C:\Users\owesh\AppData\Local\Programs\Python\Python312\Lib\site-packages\django\core\handlers\exception.py", line 55, in inner
    response = get_response(request)
               ^^^^^^^^^^^^^^^^^^^^^
  File "C:\Users\owesh\AppData\Local\Programs\Python\Python312\Lib\site-packages\django\core\handlers\base.py", line 197, in _get_response
    response = wrapped_callback(request, *callback_args, **callback_kwargs)
               ^^^^^^^^^^^^^^^^^^^^^^^^^^^^^^^^^^^^^^^^^^^^^^^^^^^^^^^^^^^^
  File "C:\Users\owesh\AppData\Local\Programs\Python\Python312\Lib\site-packages\django\contrib\auth\decorators.py", line 22, in _wrapper_view
    if test_func(request.user):
       ^^^^^^^^^^^^^^^^^^^^^^^
  File "C:\Users\owesh\AppData\Local\Programs\Python\Python312\Lib\site-packages\django\contrib\auth\decorators.py", line 51, in <lambda>
    lambda u: u.is_authenticated,
              ^^^^^^^^^^^^^^^^^^
  File "C:\Users\owesh\AppData\Local\Programs\Python\Python312\Lib\site-packages\django\utils\functional.py", line 266, in inner
    self._setup()
  File "C:\Users\owesh\AppData\Local\Programs\Python\Python312\Lib\site-packages\django\utils\functional.py", line 419, in _setup
    self._wrapped = self._setupfunc()
                    ^^^^^^^^^^^^^^^^^
  File "C:\Users\owesh\AppData\Local\Programs\Python\Python312\Lib\site-packages\django\contrib\auth\middleware.py", line 25, in <lambda>
    request.user = SimpleLazyObject(lambda: get_user(request))
                                            ^^^^^^^^^^^^^^^^^
  File "C:\Users\owesh\AppData\Local\Programs\Python\Python312\Lib\site-packages\django\contrib\auth\middleware.py", line 11, in get_user
    request._cached_user = auth.get_user(request)
                           ^^^^^^^^^^^^^^^^^^^^^^
  File "C:\Users\owesh\AppData\Local\Programs\Python\Python312\Lib\site-packages\django\contrib\auth\__init__.py", line 198, in get_user
    user = backend.get_user(user_id)
           ^^^^^^^^^^^^^^^^^^^^^^^^^
  File "C:\Users\owesh\AppData\Local\Programs\Python\Python312\Lib\site-packages\django\contrib\auth\backends.py", line 161, in get_user
    user = UserModel._default_manager.get(pk=user_id)
           ^^^^^^^^^^^^^^^^^^^^^^^^^^^^^^^^^^^^^^^^^^
  File "C:\Users\owesh\AppData\Local\Programs\Python\Python312\Lib\site-packages\django\db\models\manager.py", line 87, in manager_method
    return getattr(self.get_queryset(), name)(*args, **kwargs)
           ^^^^^^^^^^^^^^^^^^^^^^^^^^^^^^^^^^^^^^^^^^^^^^^^^^^
  File "C:\Users\owesh\AppData\Local\Programs\Python\Python312\Lib\site-packages\django\db\models\query.py", line 633, in get
    num = len(clone)
          ^^^^^^^^^^
  File "C:\Users\owesh\AppData\Local\Programs\Python\Python312\Lib\site-packages\django\db\models\query.py", line 380, in __len__
    self._fetch_all()
  File "C:\Users\owesh\AppData\Local\Programs\Python\Python312\Lib\site-packages\django\db\models\query.py", line 1881, in _fetch_all
    self._result_cache = list(self._iterable_class(self))
                         ^^^^^^^^^^^^^^^^^^^^^^^^^^^^^^^^
  File "C:\Users\owesh\AppData\Local\Programs\Python\Python312\Lib\site-packages\django\db\models\query.py", line 91, in __iter__
    results = compiler.execute_sql(
              ^^^^^^^^^^^^^^^^^^^^^
  File "C:\Users\owesh\AppData\Local\Programs\Python\Python312\Lib\site-packages\django\db\models\sql\compiler.py", line 1562, in execute_sql
    cursor.execute(sql, params)
  File "C:\Users\owesh\AppData\Local\Programs\Python\Python312\Lib\site-packages\django\db\backends\utils.py", line 102, in execute
    return super().execute(sql, params)
           ^^^^^^^^^^^^^^^^^^^^^^^^^^^^
  File "C:\Users\owesh\AppData\Local\Programs\Python\Python312\Lib\site-packages\django\db\backends\utils.py", line 67, in execute
    return self._execute_with_wrappers(
           ^^^^^^^^^^^^^^^^^^^^^^^^^^^^
  File "C:\Users\owesh\AppData\Local\Programs\Python\Python312\Lib\site-packages\django\db\backends\utils.py", line 80, in _execute_with_wrappers
    return executor(sql, params, many, context)
           ^^^^^^^^^^^^^^^^^^^^^^^^^^^^^^^^^^^^
  File "C:\Users\owesh\AppData\Local\Programs\Python\Python312\Lib\site-packages\django\db\backends\utils.py", line 84, in _execute
    with self.db.wrap_database_errors:
  File "C:\Users\owesh\AppData\Local\Programs\Python\Python312\Lib\site-packages\django\db\utils.py", line 91, in __exit__
    raise dj_exc_value.with_traceback(traceback) from exc_value
  File "C:\Users\owesh\AppData\Local\Programs\Python\Python312\Lib\site-packages\django\db\backends\utils.py", line 89, in _execute
    return self.cursor.execute(sql, params)
           ^^^^^^^^^^^^^^^^^^^^^^^^^^^^^^^^
  File "C:\Users\owesh\AppData\Local\Programs\Python\Python312\Lib\site-packages\psycopg\cursor.py", line 97, in execute
    raise ex.with_traceback(None)
django.db.utils.ProgrammingError: column accounts_customuser.is_email_verified does not exist
LINE 1: ...ser"."company_id", "accounts_customuser"."phone", "accounts_...
                                                             ^
Internal Server Error: /dashboard/drivers/
Traceback (most recent call last):
  File "C:\Users\owesh\AppData\Local\Programs\Python\Python312\Lib\site-packages\django\db\backends\utils.py", line 89, in _execute
    return self.cursor.execute(sql, params)
           ^^^^^^^^^^^^^^^^^^^^^^^^^^^^^^^^
  File "C:\Users\owesh\AppData\Local\Programs\Python\Python312\Lib\site-packages\psycopg\cursor.py", line 97, in execute
    raise ex.with_traceback(None)
psycopg.errors.UndefinedColumn: column accounts_customuser.is_email_verified does not exist
LINE 1: ...ser"."company_id", "accounts_customuser"."phone", "accounts_...
                                                             ^

The above exception was the direct cause of the following exception:

Traceback (most recent call last):
  File "C:\Users\owesh\AppData\Local\Programs\Python\Python312\Lib\site-packages\django\core\handlers\exception.py", line 55, in inner
    response = get_response(request)
               ^^^^^^^^^^^^^^^^^^^^^
  File "C:\Users\owesh\AppData\Local\Programs\Python\Python312\Lib\site-packages\django\core\handlers\base.py", line 197, in _get_response
    response = wrapped_callback(request, *callback_args, **callback_kwargs)
               ^^^^^^^^^^^^^^^^^^^^^^^^^^^^^^^^^^^^^^^^^^^^^^^^^^^^^^^^^^^^
  File "C:\Users\owesh\AppData\Local\Programs\Python\Python312\Lib\site-packages\django\contrib\auth\decorators.py", line 22, in _wrapper_view
    if test_func(request.user):
       ^^^^^^^^^^^^^^^^^^^^^^^
  File "C:\Users\owesh\AppData\Local\Programs\Python\Python312\Lib\site-packages\django\contrib\auth\decorators.py", line 51, in <lambda>
    lambda u: u.is_authenticated,
              ^^^^^^^^^^^^^^^^^^
  File "C:\Users\owesh\AppData\Local\Programs\Python\Python312\Lib\site-packages\django\utils\functional.py", line 266, in inner
    self._setup()
  File "C:\Users\owesh\AppData\Local\Programs\Python\Python312\Lib\site-packages\django\utils\functional.py", line 419, in _setup
    self._wrapped = self._setupfunc()
                    ^^^^^^^^^^^^^^^^^
  File "C:\Users\owesh\AppData\Local\Programs\Python\Python312\Lib\site-packages\django\contrib\auth\middleware.py", line 25, in <lambda>
    request.user = SimpleLazyObject(lambda: get_user(request))
                                            ^^^^^^^^^^^^^^^^^
  File "C:\Users\owesh\AppData\Local\Programs\Python\Python312\Lib\site-packages\django\contrib\auth\middleware.py", line 11, in get_user
    request._cached_user = auth.get_user(request)
                           ^^^^^^^^^^^^^^^^^^^^^^
  File "C:\Users\owesh\AppData\Local\Programs\Python\Python312\Lib\site-packages\django\contrib\auth\__init__.py", line 198, in get_user
    user = backend.get_user(user_id)
           ^^^^^^^^^^^^^^^^^^^^^^^^^
  File "C:\Users\owesh\AppData\Local\Programs\Python\Python312\Lib\site-packages\django\contrib\auth\backends.py", line 161, in get_user
    user = UserModel._default_manager.get(pk=user_id)
           ^^^^^^^^^^^^^^^^^^^^^^^^^^^^^^^^^^^^^^^^^^
  File "C:\Users\owesh\AppData\Local\Programs\Python\Python312\Lib\site-packages\django\db\models\manager.py", line 87, in manager_method
    return getattr(self.get_queryset(), name)(*args, **kwargs)
           ^^^^^^^^^^^^^^^^^^^^^^^^^^^^^^^^^^^^^^^^^^^^^^^^^^^
  File "C:\Users\owesh\AppData\Local\Programs\Python\Python312\Lib\site-packages\django\db\models\query.py", line 633, in get
    num = len(clone)
          ^^^^^^^^^^
  File "C:\Users\owesh\AppData\Local\Programs\Python\Python312\Lib\site-packages\django\db\models\query.py", line 380, in __len__
    self._fetch_all()
  File "C:\Users\owesh\AppData\Local\Programs\Python\Python312\Lib\site-packages\django\db\models\query.py", line 1881, in _fetch_all
    self._result_cache = list(self._iterable_class(self))
                         ^^^^^^^^^^^^^^^^^^^^^^^^^^^^^^^^
  File "C:\Users\owesh\AppData\Local\Programs\Python\Python312\Lib\site-packages\django\db\models\query.py", line 91, in __iter__
    results = compiler.execute_sql(
              ^^^^^^^^^^^^^^^^^^^^^
  File "C:\Users\owesh\AppData\Local\Programs\Python\Python312\Lib\site-packages\django\db\models\sql\compiler.py", line 1562, in execute_sql
    cursor.execute(sql, params)
  File "C:\Users\owesh\AppData\Local\Programs\Python\Python312\Lib\site-packages\django\db\backends\utils.py", line 102, in execute
    return super().execute(sql, params)
           ^^^^^^^^^^^^^^^^^^^^^^^^^^^^
  File "C:\Users\owesh\AppData\Local\Programs\Python\Python312\Lib\site-packages\django\db\backends\utils.py", line 67, in execute
    return self._execute_with_wrappers(
           ^^^^^^^^^^^^^^^^^^^^^^^^^^^^
  File "C:\Users\owesh\AppData\Local\Programs\Python\Python312\Lib\site-packages\django\db\backends\utils.py", line 80, in _execute_with_wrappers
    return executor(sql, params, many, context)
           ^^^^^^^^^^^^^^^^^^^^^^^^^^^^^^^^^^^^
  File "C:\Users\owesh\AppData\Local\Programs\Python\Python312\Lib\site-packages\django\db\backends\utils.py", line 84, in _execute
    with self.db.wrap_database_errors:
  File "C:\Users\owesh\AppData\Local\Programs\Python\Python312\Lib\site-packages\django\db\utils.py", line 91, in __exit__
    raise dj_exc_value.with_traceback(traceback) from exc_value
  File "C:\Users\owesh\AppData\Local\Programs\Python\Python312\Lib\site-packages\django\db\backends\utils.py", line 89, in _execute
    return self.cursor.execute(sql, params)
           ^^^^^^^^^^^^^^^^^^^^^^^^^^^^^^^^
  File "C:\Users\owesh\AppData\Local\Programs\Python\Python312\Lib\site-packages\psycopg\cursor.py", line 97, in execute
    raise ex.with_traceback(None)
django.db.utils.ProgrammingError: column accounts_customuser.is_email_verified does not exist
LINE 1: ...ser"."company_id", "accounts_customuser"."phone", "accounts_...
                                                             ^
Internal Server Error: /dashboard/drivers/
Traceback (most recent call last):
  File "C:\Users\owesh\AppData\Local\Programs\Python\Python312\Lib\site-packages\django\db\backends\utils.py", line 89, in _execute
    return self.cursor.execute(sql, params)
           ^^^^^^^^^^^^^^^^^^^^^^^^^^^^^^^^
  File "C:\Users\owesh\AppData\Local\Programs\Python\Python312\Lib\site-packages\psycopg\cursor.py", line 97, in execute
    raise ex.with_traceback(None)
psycopg.errors.UndefinedColumn: column accounts_customuser.is_email_verified does not exist
LINE 1: ...ser"."company_id", "accounts_customuser"."phone", "accounts_...
                                                             ^

The above exception was the direct cause of the following exception:

Traceback (most recent call last):
  File "C:\Users\owesh\AppData\Local\Programs\Python\Python312\Lib\site-packages\django\core\handlers\exception.py", line 55, in inner
    response = get_response(request)
               ^^^^^^^^^^^^^^^^^^^^^
  File "C:\Users\owesh\AppData\Local\Programs\Python\Python312\Lib\site-packages\django\core\handlers\base.py", line 197, in _get_response
    response = wrapped_callback(request, *callback_args, **callback_kwargs)
               ^^^^^^^^^^^^^^^^^^^^^^^^^^^^^^^^^^^^^^^^^^^^^^^^^^^^^^^^^^^^
  File "C:\Users\owesh\AppData\Local\Programs\Python\Python312\Lib\site-packages\django\contrib\auth\decorators.py", line 22, in _wrapper_view
    if test_func(request.user):
       ^^^^^^^^^^^^^^^^^^^^^^^
  File "C:\Users\owesh\AppData\Local\Programs\Python\Python312\Lib\site-packages\django\contrib\auth\decorators.py", line 51, in <lambda>
    lambda u: u.is_authenticated,
              ^^^^^^^^^^^^^^^^^^
  File "C:\Users\owesh\AppData\Local\Programs\Python\Python312\Lib\site-packages\django\utils\functional.py", line 266, in inner
    self._setup()
  File "C:\Users\owesh\AppData\Local\Programs\Python\Python312\Lib\site-packages\django\utils\functional.py", line 419, in _setup
    self._wrapped = self._setupfunc()
                    ^^^^^^^^^^^^^^^^^
  File "C:\Users\owesh\AppData\Local\Programs\Python\Python312\Lib\site-packages\django\contrib\auth\middleware.py", line 25, in <lambda>
    request.user = SimpleLazyObject(lambda: get_user(request))
                                            ^^^^^^^^^^^^^^^^^
  File "C:\Users\owesh\AppData\Local\Programs\Python\Python312\Lib\site-packages\django\contrib\auth\middleware.py", line 11, in get_user
    request._cached_user = auth.get_user(request)
                           ^^^^^^^^^^^^^^^^^^^^^^
  File "C:\Users\owesh\AppData\Local\Programs\Python\Python312\Lib\site-packages\django\contrib\auth\__init__.py", line 198, in get_user
    user = backend.get_user(user_id)
           ^^^^^^^^^^^^^^^^^^^^^^^^^
  File "C:\Users\owesh\AppData\Local\Programs\Python\Python312\Lib\site-packages\django\contrib\auth\backends.py", line 161, in get_user
    user = UserModel._default_manager.get(pk=user_id)
           ^^^^^^^^^^^^^^^^^^^^^^^^^^^^^^^^^^^^^^^^^^
  File "C:\Users\owesh\AppData\Local\Programs\Python\Python312\Lib\site-packages\django\db\models\manager.py", line 87, in manager_method
    return getattr(self.get_queryset(), name)(*args, **kwargs)
           ^^^^^^^^^^^^^^^^^^^^^^^^^^^^^^^^^^^^^^^^^^^^^^^^^^^
  File "C:\Users\owesh\AppData\Local\Programs\Python\Python312\Lib\site-packages\django\db\models\query.py", line 633, in get
    num = len(clone)
          ^^^^^^^^^^
  File "C:\Users\owesh\AppData\Local\Programs\Python\Python312\Lib\site-packages\django\db\models\query.py", line 380, in __len__
    self._fetch_all()
  File "C:\Users\owesh\AppData\Local\Programs\Python\Python312\Lib\site-packages\django\db\models\query.py", line 1881, in _fetch_all
    self._result_cache = list(self._iterable_class(self))
                         ^^^^^^^^^^^^^^^^^^^^^^^^^^^^^^^^
  File "C:\Users\owesh\AppData\Local\Programs\Python\Python312\Lib\site-packages\django\db\models\query.py", line 91, in __iter__
    results = compiler.execute_sql(
              ^^^^^^^^^^^^^^^^^^^^^
  File "C:\Users\owesh\AppData\Local\Programs\Python\Python312\Lib\site-packages\django\db\models\sql\compiler.py", line 1562, in execute_sql
    cursor.execute(sql, params)
  File "C:\Users\owesh\AppData\Local\Programs\Python\Python312\Lib\site-packages\django\db\backends\utils.py", line 102, in execute
    return super().execute(sql, params)
           ^^^^^^^^^^^^^^^^^^^^^^^^^^^^
  File "C:\Users\owesh\AppData\Local\Programs\Python\Python312\Lib\site-packages\django\db\backends\utils.py", line 67, in execute
    return self._execute_with_wrappers(
           ^^^^^^^^^^^^^^^^^^^^^^^^^^^^
  File "C:\Users\owesh\AppData\Local\Programs\Python\Python312\Lib\site-packages\django\db\backends\utils.py", line 80, in _execute_with_wrappers
    return executor(sql, params, many, context)
           ^^^^^^^^^^^^^^^^^^^^^^^^^^^^^^^^^^^^
  File "C:\Users\owesh\AppData\Local\Programs\Python\Python312\Lib\site-packages\django\db\backends\utils.py", line 84, in _execute
    with self.db.wrap_database_errors:
  File "C:\Users\owesh\AppData\Local\Programs\Python\Python312\Lib\site-packages\django\db\utils.py", line 91, in __exit__
    raise dj_exc_value.with_traceback(traceback) from exc_value
  File "C:\Users\owesh\AppData\Local\Programs\Python\Python312\Lib\site-packages\django\db\backends\utils.py", line 89, in _execute
    return self.cursor.execute(sql, params)
           ^^^^^^^^^^^^^^^^^^^^^^^^^^^^^^^^
  File "C:\Users\owesh\AppData\Local\Programs\Python\Python312\Lib\site-packages\psycopg\cursor.py", line 97, in execute
    raise ex.with_traceback(None)
django.db.utils.ProgrammingError: column accounts_customuser.is_email_verified does not exist
LINE 1: ...ser"."company_id", "accounts_customuser"."phone", "accounts_...
                                                             ^
Internal Server Error: /dashboard/admin/
Traceback (most recent call last):
  File "C:\Users\owesh\AppData\Local\Programs\Python\Python312\Lib\site-packages\django\db\backends\utils.py", line 89, in _execute
    return self.cursor.execute(sql, params)
           ^^^^^^^^^^^^^^^^^^^^^^^^^^^^^^^^
  File "C:\Users\owesh\AppData\Local\Programs\Python\Python312\Lib\site-packages\psycopg\cursor.py", line 97, in execute
    raise ex.with_traceback(None)
psycopg.errors.UndefinedColumn: column accounts_customuser.is_email_verified does not exist
LINE 1: ...ser"."company_id", "accounts_customuser"."phone", "accounts_...
                                                             ^

The above exception was the direct cause of the following exception:

Traceback (most recent call last):
  File "C:\Users\owesh\AppData\Local\Programs\Python\Python312\Lib\site-packages\django\core\handlers\exception.py", line 55, in inner
    response = get_response(request)
               ^^^^^^^^^^^^^^^^^^^^^
  File "C:\Users\owesh\AppData\Local\Programs\Python\Python312\Lib\site-packages\django\core\handlers\base.py", line 197, in _get_response
    response = wrapped_callback(request, *callback_args, **callback_kwargs)
               ^^^^^^^^^^^^^^^^^^^^^^^^^^^^^^^^^^^^^^^^^^^^^^^^^^^^^^^^^^^^
  File "C:\Users\owesh\AppData\Local\Programs\Python\Python312\Lib\site-packages\django\contrib\auth\decorators.py", line 22, in _wrapper_view
    if test_func(request.user):
       ^^^^^^^^^^^^^^^^^^^^^^^
  File "C:\Users\owesh\AppData\Local\Programs\Python\Python312\Lib\site-packages\django\contrib\auth\decorators.py", line 51, in <lambda>
    lambda u: u.is_authenticated,
              ^^^^^^^^^^^^^^^^^^
  File "C:\Users\owesh\AppData\Local\Programs\Python\Python312\Lib\site-packages\django\utils\functional.py", line 266, in inner
    self._setup()
  File "C:\Users\owesh\AppData\Local\Programs\Python\Python312\Lib\site-packages\django\utils\functional.py", line 419, in _setup
    self._wrapped = self._setupfunc()
                    ^^^^^^^^^^^^^^^^^
  File "C:\Users\owesh\AppData\Local\Programs\Python\Python312\Lib\site-packages\django\contrib\auth\middleware.py", line 25, in <lambda>
    request.user = SimpleLazyObject(lambda: get_user(request))
                                            ^^^^^^^^^^^^^^^^^
  File "C:\Users\owesh\AppData\Local\Programs\Python\Python312\Lib\site-packages\django\contrib\auth\middleware.py", line 11, in get_user
    request._cached_user = auth.get_user(request)
                           ^^^^^^^^^^^^^^^^^^^^^^
  File "C:\Users\owesh\AppData\Local\Programs\Python\Python312\Lib\site-packages\django\contrib\auth\__init__.py", line 198, in get_user
    user = backend.get_user(user_id)
           ^^^^^^^^^^^^^^^^^^^^^^^^^
  File "C:\Users\owesh\AppData\Local\Programs\Python\Python312\Lib\site-packages\django\contrib\auth\backends.py", line 161, in get_user
    user = UserModel._default_manager.get(pk=user_id)
           ^^^^^^^^^^^^^^^^^^^^^^^^^^^^^^^^^^^^^^^^^^
  File "C:\Users\owesh\AppData\Local\Programs\Python\Python312\Lib\site-packages\django\db\models\manager.py", line 87, in manager_method
    return getattr(self.get_queryset(), name)(*args, **kwargs)
           ^^^^^^^^^^^^^^^^^^^^^^^^^^^^^^^^^^^^^^^^^^^^^^^^^^^
  File "C:\Users\owesh\AppData\Local\Programs\Python\Python312\Lib\site-packages\django\db\models\query.py", line 633, in get
    num = len(clone)
          ^^^^^^^^^^
  File "C:\Users\owesh\AppData\Local\Programs\Python\Python312\Lib\site-packages\django\db\models\query.py", line 380, in __len__
    self._fetch_all()
  File "C:\Users\owesh\AppData\Local\Programs\Python\Python312\Lib\site-packages\django\db\models\query.py", line 1881, in _fetch_all
    self._result_cache = list(self._iterable_class(self))
                         ^^^^^^^^^^^^^^^^^^^^^^^^^^^^^^^^
  File "C:\Users\owesh\AppData\Local\Programs\Python\Python312\Lib\site-packages\django\db\models\query.py", line 91, in __iter__
    results = compiler.execute_sql(
              ^^^^^^^^^^^^^^^^^^^^^
  File "C:\Users\owesh\AppData\Local\Programs\Python\Python312\Lib\site-packages\django\db\models\sql\compiler.py", line 1562, in execute_sql
    cursor.execute(sql, params)
  File "C:\Users\owesh\AppData\Local\Programs\Python\Python312\Lib\site-packages\django\db\backends\utils.py", line 102, in execute
    return super().execute(sql, params)
           ^^^^^^^^^^^^^^^^^^^^^^^^^^^^
  File "C:\Users\owesh\AppData\Local\Programs\Python\Python312\Lib\site-packages\django\db\backends\utils.py", line 67, in execute
    return self._execute_with_wrappers(
           ^^^^^^^^^^^^^^^^^^^^^^^^^^^^
  File "C:\Users\owesh\AppData\Local\Programs\Python\Python312\Lib\site-packages\django\db\backends\utils.py", line 80, in _execute_with_wrappers
    return executor(sql, params, many, context)
           ^^^^^^^^^^^^^^^^^^^^^^^^^^^^^^^^^^^^
  File "C:\Users\owesh\AppData\Local\Programs\Python\Python312\Lib\site-packages\django\db\backends\utils.py", line 84, in _execute
    with self.db.wrap_database_errors:
  File "C:\Users\owesh\AppData\Local\Programs\Python\Python312\Lib\site-packages\django\db\utils.py", line 91, in __exit__
    raise dj_exc_value.with_traceback(traceback) from exc_value
  File "C:\Users\owesh\AppData\Local\Programs\Python\Python312\Lib\site-packages\django\db\backends\utils.py", line 89, in _execute
    return self.cursor.execute(sql, params)
           ^^^^^^^^^^^^^^^^^^^^^^^^^^^^^^^^
  File "C:\Users\owesh\AppData\Local\Programs\Python\Python312\Lib\site-packages\psycopg\cursor.py", line 97, in execute
    raise ex.with_traceback(None)
django.db.utils.ProgrammingError: column accounts_customuser.is_email_verified does not exist
LINE 1: ...ser"."company_id", "accounts_customuser"."phone", "accounts_...
                                                             ^
D:\Dev\fuelmng\accounts\models.py changed, reloading.
Watching for file changes with StatReloader
Not Found: /dashboard/analytics-data/
D:\Dev\fuelmng\accounts\models.py changed, reloading.
Watching for file changes with StatReloader
Watching for file changes with StatReloader
Internal Server Error: /dashboard/drivers/create/
Traceback (most recent call last):
  File "C:\Users\owesh\AppData\Local\Programs\Python\Python312\Lib\site-packages\django\db\backends\utils.py", line 89, in _execute
    return self.cursor.execute(sql, params)
           ^^^^^^^^^^^^^^^^^^^^^^^^^^^^^^^^
  File "C:\Users\owesh\AppData\Local\Programs\Python\Python312\Lib\site-packages\psycopg\cursor.py", line 97, in execute
    raise ex.with_traceback(None)
psycopg.errors.UndefinedColumn: column accounts_customuser.is_email_verified does not exist
LINE 1: ...ser"."company_id", "accounts_customuser"."phone", "accounts_...
                                                             ^

The above exception was the direct cause of the following exception:

Traceback (most recent call last):
  File "C:\Users\owesh\AppData\Local\Programs\Python\Python312\Lib\site-packages\django\core\handlers\exception.py", line 55, in inner
    response = get_response(request)
               ^^^^^^^^^^^^^^^^^^^^^
  File "C:\Users\owesh\AppData\Local\Programs\Python\Python312\Lib\site-packages\django\core\handlers\base.py", line 197, in _get_response
    response = wrapped_callback(request, *callback_args, **callback_kwargs)
               ^^^^^^^^^^^^^^^^^^^^^^^^^^^^^^^^^^^^^^^^^^^^^^^^^^^^^^^^^^^^
  File "C:\Users\owesh\AppData\Local\Programs\Python\Python312\Lib\site-packages\django\contrib\auth\decorators.py", line 22, in _wrapper_view
    if test_func(request.user):
       ^^^^^^^^^^^^^^^^^^^^^^^
  File "C:\Users\owesh\AppData\Local\Programs\Python\Python312\Lib\site-packages\django\contrib\auth\decorators.py", line 51, in <lambda>
    lambda u: u.is_authenticated,
              ^^^^^^^^^^^^^^^^^^
  File "C:\Users\owesh\AppData\Local\Programs\Python\Python312\Lib\site-packages\django\utils\functional.py", line 266, in inner
    self._setup()
  File "C:\Users\owesh\AppData\Local\Programs\Python\Python312\Lib\site-packages\django\utils\functional.py", line 419, in _setup
    self._wrapped = self._setupfunc()
                    ^^^^^^^^^^^^^^^^^
  File "C:\Users\owesh\AppData\Local\Programs\Python\Python312\Lib\site-packages\django\contrib\auth\middleware.py", line 25, in <lambda>
    request.user = SimpleLazyObject(lambda: get_user(request))
                                            ^^^^^^^^^^^^^^^^^
  File "C:\Users\owesh\AppData\Local\Programs\Python\Python312\Lib\site-packages\django\contrib\auth\middleware.py", line 11, in get_user
    request._cached_user = auth.get_user(request)
                           ^^^^^^^^^^^^^^^^^^^^^^
  File "C:\Users\owesh\AppData\Local\Programs\Python\Python312\Lib\site-packages\django\contrib\auth\__init__.py", line 198, in get_user
    user = backend.get_user(user_id)
           ^^^^^^^^^^^^^^^^^^^^^^^^^
  File "C:\Users\owesh\AppData\Local\Programs\Python\Python312\Lib\site-packages\django\contrib\auth\backends.py", line 161, in get_user
    user = UserModel._default_manager.get(pk=user_id)
           ^^^^^^^^^^^^^^^^^^^^^^^^^^^^^^^^^^^^^^^^^^
  File "C:\Users\owesh\AppData\Local\Programs\Python\Python312\Lib\site-packages\django\db\models\manager.py", line 87, in manager_method
    return getattr(self.get_queryset(), name)(*args, **kwargs)
           ^^^^^^^^^^^^^^^^^^^^^^^^^^^^^^^^^^^^^^^^^^^^^^^^^^^
  File "C:\Users\owesh\AppData\Local\Programs\Python\Python312\Lib\site-packages\django\db\models\query.py", line 633, in get
    num = len(clone)
          ^^^^^^^^^^
  File "C:\Users\owesh\AppData\Local\Programs\Python\Python312\Lib\site-packages\django\db\models\query.py", line 380, in __len__
    self._fetch_all()
  File "C:\Users\owesh\AppData\Local\Programs\Python\Python312\Lib\site-packages\django\db\models\query.py", line 1881, in _fetch_all
    self._result_cache = list(self._iterable_class(self))
                         ^^^^^^^^^^^^^^^^^^^^^^^^^^^^^^^^
  File "C:\Users\owesh\AppData\Local\Programs\Python\Python312\Lib\site-packages\django\db\models\query.py", line 91, in __iter__
    results = compiler.execute_sql(
              ^^^^^^^^^^^^^^^^^^^^^
  File "C:\Users\owesh\AppData\Local\Programs\Python\Python312\Lib\site-packages\django\db\models\sql\compiler.py", line 1562, in execute_sql
    cursor.execute(sql, params)
  File "C:\Users\owesh\AppData\Local\Programs\Python\Python312\Lib\site-packages\django\db\backends\utils.py", line 102, in execute
    return super().execute(sql, params)
           ^^^^^^^^^^^^^^^^^^^^^^^^^^^^
  File "C:\Users\owesh\AppData\Local\Programs\Python\Python312\Lib\site-packages\django\db\backends\utils.py", line 67, in execute
    return self._execute_with_wrappers(
           ^^^^^^^^^^^^^^^^^^^^^^^^^^^^
  File "C:\Users\owesh\AppData\Local\Programs\Python\Python312\Lib\site-packages\django\db\backends\utils.py", line 80, in _execute_with_wrappers
    return executor(sql, params, many, context)
           ^^^^^^^^^^^^^^^^^^^^^^^^^^^^^^^^^^^^
  File "C:\Users\owesh\AppData\Local\Programs\Python\Python312\Lib\site-packages\django\db\backends\utils.py", line 84, in _execute
    with self.db.wrap_database_errors:
  File "C:\Users\owesh\AppData\Local\Programs\Python\Python312\Lib\site-packages\django\db\utils.py", line 91, in __exit__
    raise dj_exc_value.with_traceback(traceback) from exc_value
  File "C:\Users\owesh\AppData\Local\Programs\Python\Python312\Lib\site-packages\django\db\backends\utils.py", line 89, in _execute
    return self.cursor.execute(sql, params)
           ^^^^^^^^^^^^^^^^^^^^^^^^^^^^^^^^
  File "C:\Users\owesh\AppData\Local\Programs\Python\Python312\Lib\site-packages\psycopg\cursor.py", line 97, in execute
    raise ex.with_traceback(None)
django.db.utils.ProgrammingError: column accounts_customuser.is_email_verified does not exist
LINE 1: ...ser"."company_id", "accounts_customuser"."phone", "accounts_...
                                                             ^
Internal Server Error: /dashboard/drivers/create/
Traceback (most recent call last):
  File "C:\Users\owesh\AppData\Local\Programs\Python\Python312\Lib\site-packages\django\db\backends\utils.py", line 89, in _execute
    return self.cursor.execute(sql, params)
           ^^^^^^^^^^^^^^^^^^^^^^^^^^^^^^^^
  File "C:\Users\owesh\AppData\Local\Programs\Python\Python312\Lib\site-packages\psycopg\cursor.py", line 97, in execute
    raise ex.with_traceback(None)
psycopg.errors.UndefinedColumn: column accounts_customuser.is_email_verified does not exist
LINE 1: ...ser"."company_id", "accounts_customuser"."phone", "accounts_...
                                                             ^

The above exception was the direct cause of the following exception:

Traceback (most recent call last):
  File "C:\Users\owesh\AppData\Local\Programs\Python\Python312\Lib\site-packages\django\core\handlers\exception.py", line 55, in inner
    response = get_response(request)
               ^^^^^^^^^^^^^^^^^^^^^
  File "C:\Users\owesh\AppData\Local\Programs\Python\Python312\Lib\site-packages\django\core\handlers\base.py", line 197, in _get_response
    response = wrapped_callback(request, *callback_args, **callback_kwargs)
               ^^^^^^^^^^^^^^^^^^^^^^^^^^^^^^^^^^^^^^^^^^^^^^^^^^^^^^^^^^^^
  File "C:\Users\owesh\AppData\Local\Programs\Python\Python312\Lib\site-packages\django\contrib\auth\decorators.py", line 22, in _wrapper_view
    if test_func(request.user):
       ^^^^^^^^^^^^^^^^^^^^^^^
  File "C:\Users\owesh\AppData\Local\Programs\Python\Python312\Lib\site-packages\django\contrib\auth\decorators.py", line 51, in <lambda>
    lambda u: u.is_authenticated,
              ^^^^^^^^^^^^^^^^^^
  File "C:\Users\owesh\AppData\Local\Programs\Python\Python312\Lib\site-packages\django\utils\functional.py", line 266, in inner
    self._setup()
  File "C:\Users\owesh\AppData\Local\Programs\Python\Python312\Lib\site-packages\django\utils\functional.py", line 419, in _setup
    self._wrapped = self._setupfunc()
                    ^^^^^^^^^^^^^^^^^
  File "C:\Users\owesh\AppData\Local\Programs\Python\Python312\Lib\site-packages\django\contrib\auth\middleware.py", line 25, in <lambda>
    request.user = SimpleLazyObject(lambda: get_user(request))
                                            ^^^^^^^^^^^^^^^^^
  File "C:\Users\owesh\AppData\Local\Programs\Python\Python312\Lib\site-packages\django\contrib\auth\middleware.py", line 11, in get_user
    request._cached_user = auth.get_user(request)
                           ^^^^^^^^^^^^^^^^^^^^^^
  File "C:\Users\owesh\AppData\Local\Programs\Python\Python312\Lib\site-packages\django\contrib\auth\__init__.py", line 198, in get_user
    user = backend.get_user(user_id)
           ^^^^^^^^^^^^^^^^^^^^^^^^^
  File "C:\Users\owesh\AppData\Local\Programs\Python\Python312\Lib\site-packages\django\contrib\auth\backends.py", line 161, in get_user
    user = UserModel._default_manager.get(pk=user_id)
           ^^^^^^^^^^^^^^^^^^^^^^^^^^^^^^^^^^^^^^^^^^
  File "C:\Users\owesh\AppData\Local\Programs\Python\Python312\Lib\site-packages\django\db\models\manager.py", line 87, in manager_method
    return getattr(self.get_queryset(), name)(*args, **kwargs)
           ^^^^^^^^^^^^^^^^^^^^^^^^^^^^^^^^^^^^^^^^^^^^^^^^^^^
  File "C:\Users\owesh\AppData\Local\Programs\Python\Python312\Lib\site-packages\django\db\models\query.py", line 633, in get
    num = len(clone)
          ^^^^^^^^^^
  File "C:\Users\owesh\AppData\Local\Programs\Python\Python312\Lib\site-packages\django\db\models\query.py", line 380, in __len__
    self._fetch_all()
  File "C:\Users\owesh\AppData\Local\Programs\Python\Python312\Lib\site-packages\django\db\models\query.py", line 1881, in _fetch_all
    self._result_cache = list(self._iterable_class(self))
                         ^^^^^^^^^^^^^^^^^^^^^^^^^^^^^^^^
  File "C:\Users\owesh\AppData\Local\Programs\Python\Python312\Lib\site-packages\django\db\models\query.py", line 91, in __iter__
    results = compiler.execute_sql(
              ^^^^^^^^^^^^^^^^^^^^^
  File "C:\Users\owesh\AppData\Local\Programs\Python\Python312\Lib\site-packages\django\db\models\sql\compiler.py", line 1562, in execute_sql
    cursor.execute(sql, params)
  File "C:\Users\owesh\AppData\Local\Programs\Python\Python312\Lib\site-packages\django\db\backends\utils.py", line 102, in execute
    return super().execute(sql, params)
           ^^^^^^^^^^^^^^^^^^^^^^^^^^^^
  File "C:\Users\owesh\AppData\Local\Programs\Python\Python312\Lib\site-packages\django\db\backends\utils.py", line 67, in execute
    return self._execute_with_wrappers(
           ^^^^^^^^^^^^^^^^^^^^^^^^^^^^
  File "C:\Users\owesh\AppData\Local\Programs\Python\Python312\Lib\site-packages\django\db\backends\utils.py", line 80, in _execute_with_wrappers
    return executor(sql, params, many, context)
           ^^^^^^^^^^^^^^^^^^^^^^^^^^^^^^^^^^^^
  File "C:\Users\owesh\AppData\Local\Programs\Python\Python312\Lib\site-packages\django\db\backends\utils.py", line 84, in _execute
    with self.db.wrap_database_errors:
  File "C:\Users\owesh\AppData\Local\Programs\Python\Python312\Lib\site-packages\django\db\utils.py", line 91, in __exit__
    raise dj_exc_value.with_traceback(traceback) from exc_value
  File "C:\Users\owesh\AppData\Local\Programs\Python\Python312\Lib\site-packages\django\db\backends\utils.py", line 89, in _execute
    return self.cursor.execute(sql, params)
           ^^^^^^^^^^^^^^^^^^^^^^^^^^^^^^^^
  File "C:\Users\owesh\AppData\Local\Programs\Python\Python312\Lib\site-packages\psycopg\cursor.py", line 97, in execute
    raise ex.with_traceback(None)
django.db.utils.ProgrammingError: column accounts_customuser.is_email_verified does not exist
LINE 1: ...ser"."company_id", "accounts_customuser"."phone", "accounts_...
                                                             ^
Internal Server Error: /dashboard/admin/
Traceback (most recent call last):
  File "C:\Users\owesh\AppData\Local\Programs\Python\Python312\Lib\site-packages\django\db\backends\utils.py", line 89, in _execute
    return self.cursor.execute(sql, params)
           ^^^^^^^^^^^^^^^^^^^^^^^^^^^^^^^^
  File "C:\Users\owesh\AppData\Local\Programs\Python\Python312\Lib\site-packages\psycopg\cursor.py", line 97, in execute
    raise ex.with_traceback(None)
psycopg.errors.UndefinedColumn: column accounts_customuser.is_email_verified does not exist
LINE 1: ...ser"."company_id", "accounts_customuser"."phone", "accounts_...
                                                             ^

The above exception was the direct cause of the following exception:

Traceback (most recent call last):
  File "C:\Users\owesh\AppData\Local\Programs\Python\Python312\Lib\site-packages\django\core\handlers\exception.py", line 55, in inner
    response = get_response(request)
               ^^^^^^^^^^^^^^^^^^^^^
  File "C:\Users\owesh\AppData\Local\Programs\Python\Python312\Lib\site-packages\django\core\handlers\base.py", line 197, in _get_response
    response = wrapped_callback(request, *callback_args, **callback_kwargs)
               ^^^^^^^^^^^^^^^^^^^^^^^^^^^^^^^^^^^^^^^^^^^^^^^^^^^^^^^^^^^^
  File "C:\Users\owesh\AppData\Local\Programs\Python\Python312\Lib\site-packages\django\contrib\auth\decorators.py", line 22, in _wrapper_view
    if test_func(request.user):
       ^^^^^^^^^^^^^^^^^^^^^^^
  File "C:\Users\owesh\AppData\Local\Programs\Python\Python312\Lib\site-packages\django\contrib\auth\decorators.py", line 51, in <lambda>
    lambda u: u.is_authenticated,
              ^^^^^^^^^^^^^^^^^^
  File "C:\Users\owesh\AppData\Local\Programs\Python\Python312\Lib\site-packages\django\utils\functional.py", line 266, in inner
    self._setup()
  File "C:\Users\owesh\AppData\Local\Programs\Python\Python312\Lib\site-packages\django\utils\functional.py", line 419, in _setup
    self._wrapped = self._setupfunc()
                    ^^^^^^^^^^^^^^^^^
  File "C:\Users\owesh\AppData\Local\Programs\Python\Python312\Lib\site-packages\django\contrib\auth\middleware.py", line 25, in <lambda>
    request.user = SimpleLazyObject(lambda: get_user(request))
                                            ^^^^^^^^^^^^^^^^^
  File "C:\Users\owesh\AppData\Local\Programs\Python\Python312\Lib\site-packages\django\contrib\auth\middleware.py", line 11, in get_user
    request._cached_user = auth.get_user(request)
                           ^^^^^^^^^^^^^^^^^^^^^^
  File "C:\Users\owesh\AppData\Local\Programs\Python\Python312\Lib\site-packages\django\contrib\auth\__init__.py", line 198, in get_user
    user = backend.get_user(user_id)
           ^^^^^^^^^^^^^^^^^^^^^^^^^
  File "C:\Users\owesh\AppData\Local\Programs\Python\Python312\Lib\site-packages\django\contrib\auth\backends.py", line 161, in get_user
    user = UserModel._default_manager.get(pk=user_id)
           ^^^^^^^^^^^^^^^^^^^^^^^^^^^^^^^^^^^^^^^^^^
  File "C:\Users\owesh\AppData\Local\Programs\Python\Python312\Lib\site-packages\django\db\models\manager.py", line 87, in manager_method
    return getattr(self.get_queryset(), name)(*args, **kwargs)
           ^^^^^^^^^^^^^^^^^^^^^^^^^^^^^^^^^^^^^^^^^^^^^^^^^^^
  File "C:\Users\owesh\AppData\Local\Programs\Python\Python312\Lib\site-packages\django\db\models\query.py", line 633, in get
    num = len(clone)
          ^^^^^^^^^^
  File "C:\Users\owesh\AppData\Local\Programs\Python\Python312\Lib\site-packages\django\db\models\query.py", line 380, in __len__
    self._fetch_all()
  File "C:\Users\owesh\AppData\Local\Programs\Python\Python312\Lib\site-packages\django\db\models\query.py", line 1881, in _fetch_all
    self._result_cache = list(self._iterable_class(self))
                         ^^^^^^^^^^^^^^^^^^^^^^^^^^^^^^^^
  File "C:\Users\owesh\AppData\Local\Programs\Python\Python312\Lib\site-packages\django\db\models\query.py", line 91, in __iter__
    results = compiler.execute_sql(
              ^^^^^^^^^^^^^^^^^^^^^
  File "C:\Users\owesh\AppData\Local\Programs\Python\Python312\Lib\site-packages\django\db\models\sql\compiler.py", line 1562, in execute_sql
    cursor.execute(sql, params)
  File "C:\Users\owesh\AppData\Local\Programs\Python\Python312\Lib\site-packages\django\db\backends\utils.py", line 102, in execute
    return super().execute(sql, params)
           ^^^^^^^^^^^^^^^^^^^^^^^^^^^^
  File "C:\Users\owesh\AppData\Local\Programs\Python\Python312\Lib\site-packages\django\db\backends\utils.py", line 67, in execute
    return self._execute_with_wrappers(
           ^^^^^^^^^^^^^^^^^^^^^^^^^^^^
  File "C:\Users\owesh\AppData\Local\Programs\Python\Python312\Lib\site-packages\django\db\backends\utils.py", line 80, in _execute_with_wrappers
    return executor(sql, params, many, context)
           ^^^^^^^^^^^^^^^^^^^^^^^^^^^^^^^^^^^^
  File "C:\Users\owesh\AppData\Local\Programs\Python\Python312\Lib\site-packages\django\db\backends\utils.py", line 84, in _execute
    with self.db.wrap_database_errors:
  File "C:\Users\owesh\AppData\Local\Programs\Python\Python312\Lib\site-packages\django\db\utils.py", line 91, in __exit__
    raise dj_exc_value.with_traceback(traceback) from exc_value
  File "C:\Users\owesh\AppData\Local\Programs\Python\Python312\Lib\site-packages\django\db\backends\utils.py", line 89, in _execute
    return self.cursor.execute(sql, params)
           ^^^^^^^^^^^^^^^^^^^^^^^^^^^^^^^^
  File "C:\Users\owesh\AppData\Local\Programs\Python\Python312\Lib\site-packages\psycopg\cursor.py", line 97, in execute
    raise ex.with_traceback(None)
django.db.utils.ProgrammingError: column accounts_customuser.is_email_verified does not exist
LINE 1: ...ser"."company_id", "accounts_customuser"."phone", "accounts_...
                                                             ^
D:\Dev\fuelmng\accounts\models.py changed, reloading.
Watching for file changes with StatReloader
Not Found: /dashboard/analytics-data/
